ERROR 2017-03-10 12:32:18,528: root: handle_failure: 1286: process() got an unexpected keyword argument 'dag_run': ()
Traceback (most recent call last):
  File "/home/fartash/anaconda3/envs/Etl-boilerplate/lib/python2.7/site-packages/airflow/models.py", line 1245, in run
    result = task_copy.execute(context=context)
  File "/home/fartash/anaconda3/envs/Etl-boilerplate/lib/python2.7/site-packages/airflow/operators/python_operator.py", line 66, in execute
    return_value = self.python_callable(*self.op_args, **self.op_kwargs)
TypeError: process() got an unexpected keyword argument 'dag_run'
ERROR 2017-03-10 12:32:18,532: root: handle_failure: 1327: process() got an unexpected keyword argument 'dag_run': ()
ERROR 2017-03-10 12:37:57,016: root: handle_failure: 1286: process() got an unexpected keyword argument 'dag_run': ()
Traceback (most recent call last):
  File "/home/fartash/anaconda3/envs/Etl-boilerplate/lib/python2.7/site-packages/airflow/models.py", line 1245, in run
    result = task_copy.execute(context=context)
  File "/home/fartash/anaconda3/envs/Etl-boilerplate/lib/python2.7/site-packages/airflow/operators/python_operator.py", line 66, in execute
    return_value = self.python_callable(*self.op_args, **self.op_kwargs)
TypeError: process() got an unexpected keyword argument 'dag_run'
ERROR 2017-03-10 12:37:57,017: root: handle_failure: 1327: process() got an unexpected keyword argument 'dag_run': ()
ERROR 2017-03-10 12:39:56,147: root: handle_failure: 1286: process() got an unexpected keyword argument 'dag_run': ()
Traceback (most recent call last):
  File "/home/fartash/anaconda3/envs/Etl-boilerplate/lib/python2.7/site-packages/airflow/models.py", line 1245, in run
    result = task_copy.execute(context=context)
  File "/home/fartash/anaconda3/envs/Etl-boilerplate/lib/python2.7/site-packages/airflow/operators/python_operator.py", line 66, in execute
    return_value = self.python_callable(*self.op_args, **self.op_kwargs)
TypeError: process() got an unexpected keyword argument 'dag_run'
ERROR 2017-03-10 12:39:56,149: root: handle_failure: 1327: process() got an unexpected keyword argument 'dag_run': ()
ERROR 2017-03-10 12:40:27,180: root: handle_failure: 1286: t() takes no arguments (25 given): ()
Traceback (most recent call last):
  File "/home/fartash/anaconda3/envs/Etl-boilerplate/lib/python2.7/site-packages/airflow/models.py", line 1245, in run
    result = task_copy.execute(context=context)
  File "/home/fartash/anaconda3/envs/Etl-boilerplate/lib/python2.7/site-packages/airflow/operators/python_operator.py", line 66, in execute
    return_value = self.python_callable(*self.op_args, **self.op_kwargs)
TypeError: t() takes no arguments (25 given)
ERROR 2017-03-10 12:40:27,181: root: handle_failure: 1327: t() takes no arguments (25 given): ()
ERROR 2017-03-10 12:42:45,056: root: handle_failure: 1286: : ()
Traceback (most recent call last):
  File "/home/fartash/anaconda3/envs/Etl-boilerplate/lib/python2.7/site-packages/airflow/models.py", line 1245, in run
    result = task_copy.execute(context=context)
  File "/home/fartash/anaconda3/envs/Etl-boilerplate/lib/python2.7/site-packages/airflow/operators/python_operator.py", line 66, in execute
    return_value = self.python_callable(*self.op_args, **self.op_kwargs)
  File "/home/fartash/Dev/ETL-boilerplate/app/extractor/twitter.py", line 28, in process
    stream.filter(track=['a'])
  File "/home/fartash/anaconda3/envs/Etl-boilerplate/lib/python2.7/site-packages/tweepy/streaming.py", line 445, in filter
    self._start(async)
  File "/home/fartash/anaconda3/envs/Etl-boilerplate/lib/python2.7/site-packages/tweepy/streaming.py", line 361, in _start
    self._run()
  File "/home/fartash/anaconda3/envs/Etl-boilerplate/lib/python2.7/site-packages/tweepy/streaming.py", line 263, in _run
    self._read_loop(resp)
  File "/home/fartash/anaconda3/envs/Etl-boilerplate/lib/python2.7/site-packages/tweepy/streaming.py", line 313, in _read_loop
    line = buf.read_line().strip()
  File "/home/fartash/anaconda3/envs/Etl-boilerplate/lib/python2.7/site-packages/tweepy/streaming.py", line 179, in read_line
    self._buffer += self._stream.read(self._chunk_size)
  File "/home/fartash/anaconda3/envs/Etl-boilerplate/lib/python2.7/site-packages/requests/packages/urllib3/response.py", line 380, in read
    data = self._fp.read(amt)
  File "/home/fartash/anaconda3/envs/Etl-boilerplate/lib/python2.7/httplib.py", line 573, in read
    return self._read_chunked(amt)
  File "/home/fartash/anaconda3/envs/Etl-boilerplate/lib/python2.7/httplib.py", line 633, in _read_chunked
    value.append(self._safe_read(amt))
  File "/home/fartash/anaconda3/envs/Etl-boilerplate/lib/python2.7/httplib.py", line 688, in _safe_read
    chunk = self.fp.read(min(amt, MAXAMOUNT))
  File "/home/fartash/anaconda3/envs/Etl-boilerplate/lib/python2.7/socket.py", line 384, in read
    data = self._sock.recv(left)
  File "/home/fartash/anaconda3/envs/Etl-boilerplate/lib/python2.7/ssl.py", line 766, in recv
    return self.read(buflen)
  File "/home/fartash/anaconda3/envs/Etl-boilerplate/lib/python2.7/ssl.py", line 653, in read
    v = self._sslobj.read(len)
KeyboardInterrupt
ERROR 2017-03-10 12:42:45,067: root: handle_failure: 1327: : ()
ERROR 2017-03-10 12:43:35,295: root: handle_failure: 1286: : ()
Traceback (most recent call last):
  File "/home/fartash/anaconda3/envs/Etl-boilerplate/lib/python2.7/site-packages/airflow/models.py", line 1245, in run
    result = task_copy.execute(context=context)
  File "/home/fartash/anaconda3/envs/Etl-boilerplate/lib/python2.7/site-packages/airflow/operators/python_operator.py", line 66, in execute
    return_value = self.python_callable(*self.op_args, **self.op_kwargs)
  File "/home/fartash/Dev/ETL-boilerplate/app/extractor/twitter.py", line 28, in process
    stream.filter(track=kwargs.get('query'))
  File "/home/fartash/anaconda3/envs/Etl-boilerplate/lib/python2.7/site-packages/tweepy/streaming.py", line 445, in filter
    self._start(async)
  File "/home/fartash/anaconda3/envs/Etl-boilerplate/lib/python2.7/site-packages/tweepy/streaming.py", line 361, in _start
    self._run()
  File "/home/fartash/anaconda3/envs/Etl-boilerplate/lib/python2.7/site-packages/tweepy/streaming.py", line 263, in _run
    self._read_loop(resp)
  File "/home/fartash/anaconda3/envs/Etl-boilerplate/lib/python2.7/site-packages/tweepy/streaming.py", line 322, in _read_loop
    next_status_obj = buf.read_len(length)
  File "/home/fartash/anaconda3/envs/Etl-boilerplate/lib/python2.7/site-packages/tweepy/streaming.py", line 163, in read_len
    self._buffer += self._stream.read(read_len)
  File "/home/fartash/anaconda3/envs/Etl-boilerplate/lib/python2.7/site-packages/requests/packages/urllib3/response.py", line 380, in read
    data = self._fp.read(amt)
  File "/home/fartash/anaconda3/envs/Etl-boilerplate/lib/python2.7/httplib.py", line 573, in read
    return self._read_chunked(amt)
  File "/home/fartash/anaconda3/envs/Etl-boilerplate/lib/python2.7/httplib.py", line 637, in _read_chunked
    value.append(self._safe_read(amt))
  File "/home/fartash/anaconda3/envs/Etl-boilerplate/lib/python2.7/httplib.py", line 688, in _safe_read
    chunk = self.fp.read(min(amt, MAXAMOUNT))
  File "/home/fartash/anaconda3/envs/Etl-boilerplate/lib/python2.7/socket.py", line 384, in read
    data = self._sock.recv(left)
  File "/home/fartash/anaconda3/envs/Etl-boilerplate/lib/python2.7/ssl.py", line 766, in recv
    return self.read(buflen)
  File "/home/fartash/anaconda3/envs/Etl-boilerplate/lib/python2.7/ssl.py", line 653, in read
    v = self._sslobj.read(len)
KeyboardInterrupt
ERROR 2017-03-10 12:43:35,302: root: handle_failure: 1327: : ()
ERROR 2017-03-10 13:17:08,332: root: handle_failure: 1286: ('Connection broken: IncompleteRead(0 bytes read, 4048 more expected)', IncompleteRead(0 bytes read, 4048 more expected)): ()
Traceback (most recent call last):
  File "/home/fartash/anaconda3/envs/Etl-boilerplate/lib/python2.7/site-packages/airflow/models.py", line 1245, in run
    result = task_copy.execute(context=context)
  File "/home/fartash/anaconda3/envs/Etl-boilerplate/lib/python2.7/site-packages/airflow/operators/python_operator.py", line 66, in execute
    return_value = self.python_callable(*self.op_args, **self.op_kwargs)
  File "/home/fartash/Dev/ETL-boilerplate/app/extractor/twitter.py", line 28, in process
    stream.filter(track=kwargs.get('query'))
  File "/home/fartash/anaconda3/envs/Etl-boilerplate/lib/python2.7/site-packages/tweepy/streaming.py", line 445, in filter
    self._start(async)
  File "/home/fartash/anaconda3/envs/Etl-boilerplate/lib/python2.7/site-packages/tweepy/streaming.py", line 361, in _start
    self._run()
  File "/home/fartash/anaconda3/envs/Etl-boilerplate/lib/python2.7/site-packages/tweepy/streaming.py", line 294, in _run
    raise exception
ProtocolError: ('Connection broken: IncompleteRead(0 bytes read, 4048 more expected)', IncompleteRead(0 bytes read, 4048 more expected))
ERROR 2017-03-10 13:17:08,364: root: handle_failure: 1327: ('Connection broken: IncompleteRead(0 bytes read, 4048 more expected)', IncompleteRead(0 bytes read, 4048 more expected)): ()
ERROR 2017-03-10 17:57:14,090: airflow.www.app: log_exception: 1423: Exception on /admin/airflow/graph [GET]: ()
Traceback (most recent call last):
  File "/home/fartash/anaconda3/envs/Etl-boilerplate/lib/python2.7/site-packages/flask/app.py", line 1817, in wsgi_app
    response = self.full_dispatch_request()
  File "/home/fartash/anaconda3/envs/Etl-boilerplate/lib/python2.7/site-packages/flask/app.py", line 1477, in full_dispatch_request
    rv = self.handle_user_exception(e)
  File "/home/fartash/anaconda3/envs/Etl-boilerplate/lib/python2.7/site-packages/flask/app.py", line 1381, in handle_user_exception
    reraise(exc_type, exc_value, tb)
  File "/home/fartash/anaconda3/envs/Etl-boilerplate/lib/python2.7/site-packages/flask/app.py", line 1475, in full_dispatch_request
    rv = self.dispatch_request()
  File "/home/fartash/anaconda3/envs/Etl-boilerplate/lib/python2.7/site-packages/flask/app.py", line 1461, in dispatch_request
    return self.view_functions[rule.endpoint](**req.view_args)
  File "/home/fartash/anaconda3/envs/Etl-boilerplate/lib/python2.7/site-packages/flask_admin/base.py", line 68, in inner
    return self._run_view(f, *args, **kwargs)
  File "/home/fartash/anaconda3/envs/Etl-boilerplate/lib/python2.7/site-packages/flask_admin/base.py", line 367, in _run_view
    return fn(self, *args, **kwargs)
  File "/home/fartash/anaconda3/envs/Etl-boilerplate/lib/python2.7/site-packages/flask_login.py", line 755, in decorated_view
    return func(*args, **kwargs)
  File "/home/fartash/anaconda3/envs/Etl-boilerplate/lib/python2.7/site-packages/airflow/www/utils.py", line 213, in view_func
    return f(*args, **kwargs)
  File "/home/fartash/anaconda3/envs/Etl-boilerplate/lib/python2.7/site-packages/airflow/www/utils.py", line 118, in wrapper
    return f(*args, **kwargs)
  File "/home/fartash/anaconda3/envs/Etl-boilerplate/lib/python2.7/site-packages/airflow/www/views.py", line 1311, in graph
    dag = dagbag.get_dag(dag_id)
  File "/home/fartash/anaconda3/envs/Etl-boilerplate/lib/python2.7/site-packages/airflow/models.py", line 198, in get_dag
    filepath=orm_dag.fileloc, only_if_updated=False)
  File "/home/fartash/anaconda3/envs/Etl-boilerplate/lib/python2.7/site-packages/airflow/models.py", line 214, in process_file
    if not os.path.isfile(filepath):
  File "/home/fartash/anaconda3/envs/Etl-boilerplate/lib/python2.7/genericpath.py", line 37, in isfile
    st = os.stat(path)
TypeError: coercing to Unicode: need string or buffer, NoneType found
ERROR 2017-03-10 17:59:33,308: root: handle_failure: 1286: process() takes exactly 2 arguments (1 given): ()
Traceback (most recent call last):
  File "/home/fartash/anaconda3/envs/Etl-boilerplate/lib/python2.7/site-packages/airflow/models.py", line 1245, in run
    result = task_copy.execute(context=context)
  File "/home/fartash/anaconda3/envs/Etl-boilerplate/lib/python2.7/site-packages/airflow/operators/python_operator.py", line 66, in execute
    return_value = self.python_callable(*self.op_args, **self.op_kwargs)
TypeError: process() takes exactly 2 arguments (1 given)
ERROR 2017-03-10 17:59:33,323: root: handle_failure: 1327: process() takes exactly 2 arguments (1 given): ()
ERROR 2017-03-10 17:59:37,120: root: handle_failure: 1286: process() takes exactly 2 arguments (1 given): ()
Traceback (most recent call last):
  File "/home/fartash/anaconda3/envs/Etl-boilerplate/lib/python2.7/site-packages/airflow/models.py", line 1245, in run
    result = task_copy.execute(context=context)
  File "/home/fartash/anaconda3/envs/Etl-boilerplate/lib/python2.7/site-packages/airflow/operators/python_operator.py", line 66, in execute
    return_value = self.python_callable(*self.op_args, **self.op_kwargs)
TypeError: process() takes exactly 2 arguments (1 given)
ERROR 2017-03-10 17:59:37,133: root: handle_failure: 1327: process() takes exactly 2 arguments (1 given): ()
ERROR 2017-03-10 17:59:43,445: root: handle_failure: 1286: process() takes exactly 2 arguments (1 given): ()
Traceback (most recent call last):
  File "/home/fartash/anaconda3/envs/Etl-boilerplate/lib/python2.7/site-packages/airflow/models.py", line 1245, in run
    result = task_copy.execute(context=context)
  File "/home/fartash/anaconda3/envs/Etl-boilerplate/lib/python2.7/site-packages/airflow/operators/python_operator.py", line 66, in execute
    return_value = self.python_callable(*self.op_args, **self.op_kwargs)
TypeError: process() takes exactly 2 arguments (1 given)
ERROR 2017-03-10 17:59:43,458: root: handle_failure: 1327: process() takes exactly 2 arguments (1 given): ()
ERROR 2017-03-10 18:01:07,235: root: handle_failure: 1286: process() takes exactly 2 arguments (1 given): ()
Traceback (most recent call last):
  File "/home/fartash/anaconda3/envs/Etl-boilerplate/lib/python2.7/site-packages/airflow/models.py", line 1245, in run
    result = task_copy.execute(context=context)
  File "/home/fartash/anaconda3/envs/Etl-boilerplate/lib/python2.7/site-packages/airflow/operators/python_operator.py", line 66, in execute
    return_value = self.python_callable(*self.op_args, **self.op_kwargs)
TypeError: process() takes exactly 2 arguments (1 given)
ERROR 2017-03-10 18:01:07,247: root: handle_failure: 1327: process() takes exactly 2 arguments (1 given): ()
ERROR 2017-03-10 18:01:11,770: root: handle_failure: 1286: process() takes exactly 2 arguments (1 given): ()
Traceback (most recent call last):
  File "/home/fartash/anaconda3/envs/Etl-boilerplate/lib/python2.7/site-packages/airflow/models.py", line 1245, in run
    result = task_copy.execute(context=context)
  File "/home/fartash/anaconda3/envs/Etl-boilerplate/lib/python2.7/site-packages/airflow/operators/python_operator.py", line 66, in execute
    return_value = self.python_callable(*self.op_args, **self.op_kwargs)
TypeError: process() takes exactly 2 arguments (1 given)
ERROR 2017-03-10 18:01:11,777: root: handle_failure: 1327: process() takes exactly 2 arguments (1 given): ()
ERROR 2017-03-10 18:03:28,548: root: handle_failure: 1286: process() takes exactly 2 arguments (1 given): ()
Traceback (most recent call last):
  File "/home/fartash/anaconda3/envs/Etl-boilerplate/lib/python2.7/site-packages/airflow/models.py", line 1245, in run
    result = task_copy.execute(context=context)
  File "/home/fartash/anaconda3/envs/Etl-boilerplate/lib/python2.7/site-packages/airflow/operators/python_operator.py", line 66, in execute
    return_value = self.python_callable(*self.op_args, **self.op_kwargs)
TypeError: process() takes exactly 2 arguments (1 given)
ERROR 2017-03-10 18:03:28,549: root: handle_failure: 1327: process() takes exactly 2 arguments (1 given): ()
ERROR 2017-03-10 18:04:11,201: root: handle_failure: 1286: load_into_elastic() takes exactly 2 arguments (1 given): ()
Traceback (most recent call last):
  File "/home/fartash/anaconda3/envs/Etl-boilerplate/lib/python2.7/site-packages/airflow/models.py", line 1245, in run
    result = task_copy.execute(context=context)
  File "/home/fartash/anaconda3/envs/Etl-boilerplate/lib/python2.7/site-packages/airflow/operators/python_operator.py", line 66, in execute
    return_value = self.python_callable(*self.op_args, **self.op_kwargs)
TypeError: load_into_elastic() takes exactly 2 arguments (1 given)
ERROR 2017-03-10 18:04:11,202: root: handle_failure: 1327: load_into_elastic() takes exactly 2 arguments (1 given): ()
ERROR 2017-03-10 18:08:59,915: root: handle_failure: 1286: process() takes exactly 2 arguments (1 given): ()
Traceback (most recent call last):
  File "/home/fartash/anaconda3/envs/Etl-boilerplate/lib/python2.7/site-packages/airflow/models.py", line 1245, in run
    result = task_copy.execute(context=context)
  File "/home/fartash/anaconda3/envs/Etl-boilerplate/lib/python2.7/site-packages/airflow/operators/python_operator.py", line 66, in execute
    return_value = self.python_callable(*self.op_args, **self.op_kwargs)
TypeError: process() takes exactly 2 arguments (1 given)
ERROR 2017-03-10 18:08:59,918: root: handle_failure: 1327: process() takes exactly 2 arguments (1 given): ()
ERROR 2017-03-10 18:12:02,535: root: handle_failure: 1286: __analyze_tweets() takes exactly 1 argument (0 given): ()
Traceback (most recent call last):
  File "/home/fartash/anaconda3/envs/Etl-boilerplate/lib/python2.7/site-packages/airflow/models.py", line 1245, in run
    result = task_copy.execute(context=context)
  File "/home/fartash/anaconda3/envs/Etl-boilerplate/lib/python2.7/site-packages/airflow/operators/python_operator.py", line 66, in execute
    return_value = self.python_callable(*self.op_args, **self.op_kwargs)
TypeError: __analyze_tweets() takes exactly 1 argument (0 given)
ERROR 2017-03-10 18:12:02,536: root: handle_failure: 1327: __analyze_tweets() takes exactly 1 argument (0 given): ()
ERROR 2017-03-10 18:12:57,460: root: handle_failure: 1286: __analyze_tweets() takes exactly 1 argument (0 given): ()
Traceback (most recent call last):
  File "/home/fartash/anaconda3/envs/Etl-boilerplate/lib/python2.7/site-packages/airflow/models.py", line 1245, in run
    result = task_copy.execute(context=context)
  File "/home/fartash/anaconda3/envs/Etl-boilerplate/lib/python2.7/site-packages/airflow/operators/python_operator.py", line 66, in execute
    return_value = self.python_callable(*self.op_args, **self.op_kwargs)
TypeError: __analyze_tweets() takes exactly 1 argument (0 given)
ERROR 2017-03-10 18:12:57,462: root: handle_failure: 1327: __analyze_tweets() takes exactly 1 argument (0 given): ()
ERROR 2017-03-10 18:13:16,839: root: handle_failure: 1286: a() takes exactly 1 argument (0 given): ()
Traceback (most recent call last):
  File "/home/fartash/anaconda3/envs/Etl-boilerplate/lib/python2.7/site-packages/airflow/models.py", line 1245, in run
    result = task_copy.execute(context=context)
  File "/home/fartash/anaconda3/envs/Etl-boilerplate/lib/python2.7/site-packages/airflow/operators/python_operator.py", line 66, in execute
    return_value = self.python_callable(*self.op_args, **self.op_kwargs)
TypeError: a() takes exactly 1 argument (0 given)
ERROR 2017-03-10 18:13:16,840: root: handle_failure: 1327: a() takes exactly 1 argument (0 given): ()
ERROR 2017-03-10 18:13:45,507: root: handle_failure: 1286: __analyze_tweets() takes exactly 1 argument (0 given): ()
Traceback (most recent call last):
  File "/home/fartash/anaconda3/envs/Etl-boilerplate/lib/python2.7/site-packages/airflow/models.py", line 1245, in run
    result = task_copy.execute(context=context)
  File "/home/fartash/anaconda3/envs/Etl-boilerplate/lib/python2.7/site-packages/airflow/operators/python_operator.py", line 66, in execute
    return_value = self.python_callable(*self.op_args, **self.op_kwargs)
TypeError: __analyze_tweets() takes exactly 1 argument (0 given)
ERROR 2017-03-10 18:13:45,508: root: handle_failure: 1327: __analyze_tweets() takes exactly 1 argument (0 given): ()
ERROR 2017-03-10 18:15:39,082: root: handle_failure: 1286: unsupported operand type(s) for -: 'str' and 'datetime.timedelta': ()
Traceback (most recent call last):
  File "/home/fartash/anaconda3/envs/Etl-boilerplate/lib/python2.7/site-packages/airflow/models.py", line 1245, in run
    result = task_copy.execute(context=context)
  File "/home/fartash/anaconda3/envs/Etl-boilerplate/lib/python2.7/site-packages/airflow/operators/python_operator.py", line 66, in execute
    return_value = self.python_callable(*self.op_args, **self.op_kwargs)
  File "/home/fartash/Dev/ETL-boilerplate/airflow/dags/twitter.py", line 28, in __twitter_transformer
    twitter_transformer.process(ds,**kwargs)
  File "/home/fartash/Dev/ETL-boilerplate/app/transformer/twitter.py", line 21, in process
    raw_records = self.__fetch_tweets(dt - kwargs.get('interval'), dt)
TypeError: unsupported operand type(s) for -: 'str' and 'datetime.timedelta'
ERROR 2017-03-10 18:15:39,084: root: handle_failure: 1327: unsupported operand type(s) for -: 'str' and 'datetime.timedelta': ()
ERROR 2017-03-10 18:16:22,067: root: handle_failure: 1286: unsupported operand type(s) for -: 'str' and 'datetime.timedelta': ()
Traceback (most recent call last):
  File "/home/fartash/anaconda3/envs/Etl-boilerplate/lib/python2.7/site-packages/airflow/models.py", line 1245, in run
    result = task_copy.execute(context=context)
  File "/home/fartash/anaconda3/envs/Etl-boilerplate/lib/python2.7/site-packages/airflow/operators/python_operator.py", line 66, in execute
    return_value = self.python_callable(*self.op_args, **self.op_kwargs)
  File "/home/fartash/Dev/ETL-boilerplate/app/transformer/twitter.py", line 21, in process
    raw_records = self.__fetch_tweets(ds - kwargs.get('interval'), ds)
TypeError: unsupported operand type(s) for -: 'str' and 'datetime.timedelta'
ERROR 2017-03-10 18:16:22,069: root: handle_failure: 1327: unsupported operand type(s) for -: 'str' and 'datetime.timedelta': ()
ERROR 2017-03-10 18:29:04,847: root: handle_failure: 1286: Successful parsed but returned no results.: ()
Traceback (most recent call last):
  File "/home/fartash/anaconda3/envs/Etl-boilerplate/lib/python2.7/site-packages/airflow/models.py", line 1245, in run
    result = task_copy.execute(context=context)
  File "/home/fartash/anaconda3/envs/Etl-boilerplate/lib/python2.7/site-packages/airflow/operators/python_operator.py", line 66, in execute
    return_value = self.python_callable(*self.op_args, **self.op_kwargs)
  File "/home/fartash/Dev/ETL-boilerplate/app/transformer/twitter.py", line 31, in process
    coordinates = self.__get_go_points(tweet['user']['location'])
  File "/home/fartash/Dev/ETL-boilerplate/app/transformer/twitter.py", line 95, in __get_go_points
    res = self.googlemaps_api.search(address.strip(string.punctuation + ' ')).first()
  File "/home/fartash/anaconda3/envs/Etl-boilerplate/lib/python2.7/site-packages/geolocation/main.py", line 18, in search
    return self.geocode.search(location, lat, lng)
  File "/home/fartash/anaconda3/envs/Etl-boilerplate/lib/python2.7/site-packages/geolocation/geocode/main.py", line 48, in search
    data = self.client.get_data(address=address, latitude=latitude, longitude=longitude)
  File "/home/fartash/anaconda3/envs/Etl-boilerplate/lib/python2.7/site-packages/geolocation/geocode/client.py", line 40, in get_data
    return self.send_data(self.API_URL, self.query_parameters)
  File "/home/fartash/anaconda3/envs/Etl-boilerplate/lib/python2.7/site-packages/geolocation/client.py", line 23, in send_data
    self.validator(response)
  File "/home/fartash/anaconda3/envs/Etl-boilerplate/lib/python2.7/site-packages/geolocation/validators.py", line 28, in __init__
    self.validation(response)
  File "/home/fartash/anaconda3/envs/Etl-boilerplate/lib/python2.7/site-packages/geolocation/validators.py", line 55, in validation
    self.validate_google_status(response)
  File "/home/fartash/anaconda3/envs/Etl-boilerplate/lib/python2.7/site-packages/geolocation/validators.py", line 46, in validate_google_status
    raise ApiClientException(message)
ApiClientException: Successful parsed but returned no results.
ERROR 2017-03-10 18:29:04,877: root: handle_failure: 1327: Successful parsed but returned no results.: ()
ERROR 2017-03-10 18:29:48,492: root: handle_failure: 1286: HTTPSConnectionPool(host='maps.googleapis.com', port=443): Max retries exceeded with url: /maps/api/geocode/json?address=somewhere+with+a+Backwood (Caused by NewConnectionError('<requests.packages.urllib3.connection.VerifiedHTTPSConnection object at 0x7f74f8055710>: Failed to establish a new connection: [Errno -3] Temporary failure in name resolution',)): ()
Traceback (most recent call last):
  File "/home/fartash/anaconda3/envs/Etl-boilerplate/lib/python2.7/site-packages/airflow/models.py", line 1245, in run
    result = task_copy.execute(context=context)
  File "/home/fartash/anaconda3/envs/Etl-boilerplate/lib/python2.7/site-packages/airflow/operators/python_operator.py", line 66, in execute
    return_value = self.python_callable(*self.op_args, **self.op_kwargs)
  File "/home/fartash/Dev/ETL-boilerplate/app/transformer/twitter.py", line 31, in process
    coordinates = self.__get_go_points(tweet['user']['location'])
  File "/home/fartash/Dev/ETL-boilerplate/app/transformer/twitter.py", line 95, in __get_go_points
    res = self.googlemaps_api.search(address.strip(string.punctuation + ' ')).first()
  File "/home/fartash/anaconda3/envs/Etl-boilerplate/lib/python2.7/site-packages/geolocation/main.py", line 18, in search
    return self.geocode.search(location, lat, lng)
  File "/home/fartash/anaconda3/envs/Etl-boilerplate/lib/python2.7/site-packages/geolocation/geocode/main.py", line 48, in search
    data = self.client.get_data(address=address, latitude=latitude, longitude=longitude)
  File "/home/fartash/anaconda3/envs/Etl-boilerplate/lib/python2.7/site-packages/geolocation/geocode/client.py", line 40, in get_data
    return self.send_data(self.API_URL, self.query_parameters)
  File "/home/fartash/anaconda3/envs/Etl-boilerplate/lib/python2.7/site-packages/geolocation/client.py", line 22, in send_data
    response = requests.get(url, params=params)
  File "/home/fartash/anaconda3/envs/Etl-boilerplate/lib/python2.7/site-packages/requests/api.py", line 70, in get
    return request('get', url, params=params, **kwargs)
  File "/home/fartash/anaconda3/envs/Etl-boilerplate/lib/python2.7/site-packages/requests/api.py", line 56, in request
    return session.request(method=method, url=url, **kwargs)
  File "/home/fartash/anaconda3/envs/Etl-boilerplate/lib/python2.7/site-packages/requests/sessions.py", line 488, in request
    resp = self.send(prep, **send_kwargs)
  File "/home/fartash/anaconda3/envs/Etl-boilerplate/lib/python2.7/site-packages/requests/sessions.py", line 609, in send
    r = adapter.send(request, **kwargs)
  File "/home/fartash/anaconda3/envs/Etl-boilerplate/lib/python2.7/site-packages/requests/adapters.py", line 487, in send
    raise ConnectionError(e, request=request)
ConnectionError: HTTPSConnectionPool(host='maps.googleapis.com', port=443): Max retries exceeded with url: /maps/api/geocode/json?address=somewhere+with+a+Backwood (Caused by NewConnectionError('<requests.packages.urllib3.connection.VerifiedHTTPSConnection object at 0x7f74f8055710>: Failed to establish a new connection: [Errno -3] Temporary failure in name resolution',))
ERROR 2017-03-10 18:29:48,508: root: handle_failure: 1327: HTTPSConnectionPool(host='maps.googleapis.com', port=443): Max retries exceeded with url: /maps/api/geocode/json?address=somewhere+with+a+Backwood (Caused by NewConnectionError('<requests.packages.urllib3.connection.VerifiedHTTPSConnection object at 0x7f74f8055710>: Failed to establish a new connection: [Errno -3] Temporary failure in name resolution',)): ()
ERROR 2017-03-11 09:30:43,283: root: handle_failure: 1286: : ()
Traceback (most recent call last):
  File "/home/fartash/anaconda3/envs/Etl-boilerplate/lib/python2.7/site-packages/airflow/models.py", line 1245, in run
    result = task_copy.execute(context=context)
  File "/home/fartash/anaconda3/envs/Etl-boilerplate/lib/python2.7/site-packages/airflow/operators/python_operator.py", line 66, in execute
    return_value = self.python_callable(*self.op_args, **self.op_kwargs)
  File "/home/fartash/Dev/ETL-boilerplate/app/transformer/twitter.py", line 32, in process
    coordinates = self.__get_go_points(tweet['user']['location'])
  File "/home/fartash/Dev/ETL-boilerplate/app/transformer/twitter.py", line 96, in __get_go_points
    res = self.googlemaps_api.search(address.strip(string.punctuation + ' ')).first()
  File "/home/fartash/anaconda3/envs/Etl-boilerplate/lib/python2.7/site-packages/geolocation/main.py", line 18, in search
    return self.geocode.search(location, lat, lng)
  File "/home/fartash/anaconda3/envs/Etl-boilerplate/lib/python2.7/site-packages/geolocation/geocode/main.py", line 48, in search
    data = self.client.get_data(address=address, latitude=latitude, longitude=longitude)
  File "/home/fartash/anaconda3/envs/Etl-boilerplate/lib/python2.7/site-packages/geolocation/geocode/client.py", line 40, in get_data
    return self.send_data(self.API_URL, self.query_parameters)
  File "/home/fartash/anaconda3/envs/Etl-boilerplate/lib/python2.7/site-packages/geolocation/client.py", line 22, in send_data
    response = requests.get(url, params=params)
  File "/home/fartash/anaconda3/envs/Etl-boilerplate/lib/python2.7/site-packages/requests/api.py", line 70, in get
    return request('get', url, params=params, **kwargs)
  File "/home/fartash/anaconda3/envs/Etl-boilerplate/lib/python2.7/site-packages/requests/api.py", line 56, in request
    return session.request(method=method, url=url, **kwargs)
  File "/home/fartash/anaconda3/envs/Etl-boilerplate/lib/python2.7/site-packages/requests/sessions.py", line 488, in request
    resp = self.send(prep, **send_kwargs)
  File "/home/fartash/anaconda3/envs/Etl-boilerplate/lib/python2.7/site-packages/requests/sessions.py", line 609, in send
    r = adapter.send(request, **kwargs)
  File "/home/fartash/anaconda3/envs/Etl-boilerplate/lib/python2.7/site-packages/requests/adapters.py", line 423, in send
    timeout=timeout
  File "/home/fartash/anaconda3/envs/Etl-boilerplate/lib/python2.7/site-packages/requests/packages/urllib3/connectionpool.py", line 600, in urlopen
    chunked=chunked)
  File "/home/fartash/anaconda3/envs/Etl-boilerplate/lib/python2.7/site-packages/requests/packages/urllib3/connectionpool.py", line 345, in _make_request
    self._validate_conn(conn)
  File "/home/fartash/anaconda3/envs/Etl-boilerplate/lib/python2.7/site-packages/requests/packages/urllib3/connectionpool.py", line 844, in _validate_conn
    conn.connect()
  File "/home/fartash/anaconda3/envs/Etl-boilerplate/lib/python2.7/site-packages/requests/packages/urllib3/connection.py", line 284, in connect
    conn = self._new_conn()
  File "/home/fartash/anaconda3/envs/Etl-boilerplate/lib/python2.7/site-packages/requests/packages/urllib3/connection.py", line 141, in _new_conn
    (self.host, self.port), self.timeout, **extra_kw)
  File "/home/fartash/anaconda3/envs/Etl-boilerplate/lib/python2.7/site-packages/requests/packages/urllib3/util/connection.py", line 60, in create_connection
    for res in socket.getaddrinfo(host, port, family, socket.SOCK_STREAM):
KeyboardInterrupt
ERROR 2017-03-11 09:30:43,296: root: handle_failure: 1327: : ()
ERROR 2017-03-11 09:43:11,156: root: handle_failure: 1286: Successful parsed but returned no results.: ()
Traceback (most recent call last):
  File "/home/fartash/anaconda3/envs/Etl-boilerplate/lib/python2.7/site-packages/airflow/models.py", line 1245, in run
    result = task_copy.execute(context=context)
  File "/home/fartash/anaconda3/envs/Etl-boilerplate/lib/python2.7/site-packages/airflow/operators/python_operator.py", line 66, in execute
    return_value = self.python_callable(*self.op_args, **self.op_kwargs)
  File "/home/fartash/Dev/ETL-boilerplate/app/transformer/twitter.py", line 32, in process
    coordinates = self.__get_go_points(tweet['user']['location'])
  File "/home/fartash/Dev/ETL-boilerplate/app/transformer/twitter.py", line 96, in __get_go_points
    res = self.googlemaps_api.search(address.strip(string.punctuation + ' ')).first()
  File "/home/fartash/anaconda3/envs/Etl-boilerplate/lib/python2.7/site-packages/geolocation/main.py", line 18, in search
    return self.geocode.search(location, lat, lng)
  File "/home/fartash/anaconda3/envs/Etl-boilerplate/lib/python2.7/site-packages/geolocation/geocode/main.py", line 48, in search
    data = self.client.get_data(address=address, latitude=latitude, longitude=longitude)
  File "/home/fartash/anaconda3/envs/Etl-boilerplate/lib/python2.7/site-packages/geolocation/geocode/client.py", line 40, in get_data
    return self.send_data(self.API_URL, self.query_parameters)
  File "/home/fartash/anaconda3/envs/Etl-boilerplate/lib/python2.7/site-packages/geolocation/client.py", line 23, in send_data
    self.validator(response)
  File "/home/fartash/anaconda3/envs/Etl-boilerplate/lib/python2.7/site-packages/geolocation/validators.py", line 28, in __init__
    self.validation(response)
  File "/home/fartash/anaconda3/envs/Etl-boilerplate/lib/python2.7/site-packages/geolocation/validators.py", line 55, in validation
    self.validate_google_status(response)
  File "/home/fartash/anaconda3/envs/Etl-boilerplate/lib/python2.7/site-packages/geolocation/validators.py", line 46, in validate_google_status
    raise ApiClientException(message)
ApiClientException: Successful parsed but returned no results.
ERROR 2017-03-11 09:43:11,185: root: handle_failure: 1327: Successful parsed but returned no results.: ()
ERROR 2017-03-11 09:43:48,335: root: handle_failure: 1286: EOF occurred in violation of protocol (_ssl.c:661): ()
Traceback (most recent call last):
  File "/home/fartash/anaconda3/envs/Etl-boilerplate/lib/python2.7/site-packages/airflow/models.py", line 1245, in run
    result = task_copy.execute(context=context)
  File "/home/fartash/anaconda3/envs/Etl-boilerplate/lib/python2.7/site-packages/airflow/operators/python_operator.py", line 66, in execute
    return_value = self.python_callable(*self.op_args, **self.op_kwargs)
  File "/home/fartash/Dev/ETL-boilerplate/app/transformer/twitter.py", line 32, in process
    coordinates = self.__get_go_points(tweet['user']['location'])
  File "/home/fartash/Dev/ETL-boilerplate/app/transformer/twitter.py", line 96, in __get_go_points
    res = self.googlemaps_api.search(address.strip(string.punctuation + ' ')).first()
  File "/home/fartash/anaconda3/envs/Etl-boilerplate/lib/python2.7/site-packages/geolocation/main.py", line 18, in search
    return self.geocode.search(location, lat, lng)
  File "/home/fartash/anaconda3/envs/Etl-boilerplate/lib/python2.7/site-packages/geolocation/geocode/main.py", line 48, in search
    data = self.client.get_data(address=address, latitude=latitude, longitude=longitude)
  File "/home/fartash/anaconda3/envs/Etl-boilerplate/lib/python2.7/site-packages/geolocation/geocode/client.py", line 40, in get_data
    return self.send_data(self.API_URL, self.query_parameters)
  File "/home/fartash/anaconda3/envs/Etl-boilerplate/lib/python2.7/site-packages/geolocation/client.py", line 22, in send_data
    response = requests.get(url, params=params)
  File "/home/fartash/anaconda3/envs/Etl-boilerplate/lib/python2.7/site-packages/requests/api.py", line 70, in get
    return request('get', url, params=params, **kwargs)
  File "/home/fartash/anaconda3/envs/Etl-boilerplate/lib/python2.7/site-packages/requests/api.py", line 56, in request
    return session.request(method=method, url=url, **kwargs)
  File "/home/fartash/anaconda3/envs/Etl-boilerplate/lib/python2.7/site-packages/requests/sessions.py", line 488, in request
    resp = self.send(prep, **send_kwargs)
  File "/home/fartash/anaconda3/envs/Etl-boilerplate/lib/python2.7/site-packages/requests/sessions.py", line 609, in send
    r = adapter.send(request, **kwargs)
  File "/home/fartash/anaconda3/envs/Etl-boilerplate/lib/python2.7/site-packages/requests/adapters.py", line 497, in send
    raise SSLError(e, request=request)
SSLError: EOF occurred in violation of protocol (_ssl.c:661)
ERROR 2017-03-11 09:43:48,366: root: handle_failure: 1327: EOF occurred in violation of protocol (_ssl.c:661): ()
ERROR 2017-03-11 09:44:08,388: root: handle_failure: 1286: Successful parsed but returned no results.: ()
Traceback (most recent call last):
  File "/home/fartash/anaconda3/envs/Etl-boilerplate/lib/python2.7/site-packages/airflow/models.py", line 1245, in run
    result = task_copy.execute(context=context)
  File "/home/fartash/anaconda3/envs/Etl-boilerplate/lib/python2.7/site-packages/airflow/operators/python_operator.py", line 66, in execute
    return_value = self.python_callable(*self.op_args, **self.op_kwargs)
  File "/home/fartash/Dev/ETL-boilerplate/app/transformer/twitter.py", line 32, in process
    coordinates = self.__get_go_points(tweet['user']['location'])
  File "/home/fartash/Dev/ETL-boilerplate/app/transformer/twitter.py", line 96, in __get_go_points
    res = self.googlemaps_api.search(address.strip(string.punctuation + ' ')).first()
  File "/home/fartash/anaconda3/envs/Etl-boilerplate/lib/python2.7/site-packages/geolocation/main.py", line 18, in search
    return self.geocode.search(location, lat, lng)
  File "/home/fartash/anaconda3/envs/Etl-boilerplate/lib/python2.7/site-packages/geolocation/geocode/main.py", line 48, in search
    data = self.client.get_data(address=address, latitude=latitude, longitude=longitude)
  File "/home/fartash/anaconda3/envs/Etl-boilerplate/lib/python2.7/site-packages/geolocation/geocode/client.py", line 40, in get_data
    return self.send_data(self.API_URL, self.query_parameters)
  File "/home/fartash/anaconda3/envs/Etl-boilerplate/lib/python2.7/site-packages/geolocation/client.py", line 23, in send_data
    self.validator(response)
  File "/home/fartash/anaconda3/envs/Etl-boilerplate/lib/python2.7/site-packages/geolocation/validators.py", line 28, in __init__
    self.validation(response)
  File "/home/fartash/anaconda3/envs/Etl-boilerplate/lib/python2.7/site-packages/geolocation/validators.py", line 55, in validation
    self.validate_google_status(response)
  File "/home/fartash/anaconda3/envs/Etl-boilerplate/lib/python2.7/site-packages/geolocation/validators.py", line 46, in validate_google_status
    raise ApiClientException(message)
ApiClientException: Successful parsed but returned no results.
ERROR 2017-03-11 09:44:08,414: root: handle_failure: 1327: Successful parsed but returned no results.: ()
ERROR 2017-03-11 09:44:24,491: root: handle_failure: 1286: Successful parsed but returned no results.: ()
Traceback (most recent call last):
  File "/home/fartash/anaconda3/envs/Etl-boilerplate/lib/python2.7/site-packages/airflow/models.py", line 1245, in run
    result = task_copy.execute(context=context)
  File "/home/fartash/anaconda3/envs/Etl-boilerplate/lib/python2.7/site-packages/airflow/operators/python_operator.py", line 66, in execute
    return_value = self.python_callable(*self.op_args, **self.op_kwargs)
  File "/home/fartash/Dev/ETL-boilerplate/app/transformer/twitter.py", line 32, in process
    coordinates = self.__get_go_points(tweet['user']['location'])
  File "/home/fartash/Dev/ETL-boilerplate/app/transformer/twitter.py", line 96, in __get_go_points
    res = self.googlemaps_api.search(address.strip(string.punctuation + ' ')).first()
  File "/home/fartash/anaconda3/envs/Etl-boilerplate/lib/python2.7/site-packages/geolocation/main.py", line 18, in search
    return self.geocode.search(location, lat, lng)
  File "/home/fartash/anaconda3/envs/Etl-boilerplate/lib/python2.7/site-packages/geolocation/geocode/main.py", line 48, in search
    data = self.client.get_data(address=address, latitude=latitude, longitude=longitude)
  File "/home/fartash/anaconda3/envs/Etl-boilerplate/lib/python2.7/site-packages/geolocation/geocode/client.py", line 40, in get_data
    return self.send_data(self.API_URL, self.query_parameters)
  File "/home/fartash/anaconda3/envs/Etl-boilerplate/lib/python2.7/site-packages/geolocation/client.py", line 23, in send_data
    self.validator(response)
  File "/home/fartash/anaconda3/envs/Etl-boilerplate/lib/python2.7/site-packages/geolocation/validators.py", line 28, in __init__
    self.validation(response)
  File "/home/fartash/anaconda3/envs/Etl-boilerplate/lib/python2.7/site-packages/geolocation/validators.py", line 55, in validation
    self.validate_google_status(response)
  File "/home/fartash/anaconda3/envs/Etl-boilerplate/lib/python2.7/site-packages/geolocation/validators.py", line 46, in validate_google_status
    raise ApiClientException(message)
ApiClientException: Successful parsed but returned no results.
ERROR 2017-03-11 09:44:24,519: root: handle_failure: 1327: Successful parsed but returned no results.: ()
ERROR 2017-03-11 09:44:41,881: root: handle_failure: 1286: EOF occurred in violation of protocol (_ssl.c:661): ()
Traceback (most recent call last):
  File "/home/fartash/anaconda3/envs/Etl-boilerplate/lib/python2.7/site-packages/airflow/models.py", line 1245, in run
    result = task_copy.execute(context=context)
  File "/home/fartash/anaconda3/envs/Etl-boilerplate/lib/python2.7/site-packages/airflow/operators/python_operator.py", line 66, in execute
    return_value = self.python_callable(*self.op_args, **self.op_kwargs)
  File "/home/fartash/Dev/ETL-boilerplate/app/transformer/twitter.py", line 32, in process
    coordinates = self.__get_go_points(tweet['user']['location'])
  File "/home/fartash/Dev/ETL-boilerplate/app/transformer/twitter.py", line 96, in __get_go_points
    res = self.googlemaps_api.search(address.strip(string.punctuation + ' ')).first()
  File "/home/fartash/anaconda3/envs/Etl-boilerplate/lib/python2.7/site-packages/geolocation/main.py", line 18, in search
    return self.geocode.search(location, lat, lng)
  File "/home/fartash/anaconda3/envs/Etl-boilerplate/lib/python2.7/site-packages/geolocation/geocode/main.py", line 48, in search
    data = self.client.get_data(address=address, latitude=latitude, longitude=longitude)
  File "/home/fartash/anaconda3/envs/Etl-boilerplate/lib/python2.7/site-packages/geolocation/geocode/client.py", line 40, in get_data
    return self.send_data(self.API_URL, self.query_parameters)
  File "/home/fartash/anaconda3/envs/Etl-boilerplate/lib/python2.7/site-packages/geolocation/client.py", line 22, in send_data
    response = requests.get(url, params=params)
  File "/home/fartash/anaconda3/envs/Etl-boilerplate/lib/python2.7/site-packages/requests/api.py", line 70, in get
    return request('get', url, params=params, **kwargs)
  File "/home/fartash/anaconda3/envs/Etl-boilerplate/lib/python2.7/site-packages/requests/api.py", line 56, in request
    return session.request(method=method, url=url, **kwargs)
  File "/home/fartash/anaconda3/envs/Etl-boilerplate/lib/python2.7/site-packages/requests/sessions.py", line 488, in request
    resp = self.send(prep, **send_kwargs)
  File "/home/fartash/anaconda3/envs/Etl-boilerplate/lib/python2.7/site-packages/requests/sessions.py", line 609, in send
    r = adapter.send(request, **kwargs)
  File "/home/fartash/anaconda3/envs/Etl-boilerplate/lib/python2.7/site-packages/requests/adapters.py", line 497, in send
    raise SSLError(e, request=request)
SSLError: EOF occurred in violation of protocol (_ssl.c:661)
ERROR 2017-03-11 09:44:41,898: root: handle_failure: 1327: EOF occurred in violation of protocol (_ssl.c:661): ()
ERROR 2017-03-11 09:57:26,001: root: handle_failure: 1286: __fetch_tweets() takes exactly 3 arguments (1 given): ()
Traceback (most recent call last):
  File "/home/fartash/anaconda3/envs/Etl-boilerplate/lib/python2.7/site-packages/airflow/models.py", line 1245, in run
    result = task_copy.execute(context=context)
  File "/home/fartash/anaconda3/envs/Etl-boilerplate/lib/python2.7/site-packages/airflow/operators/python_operator.py", line 66, in execute
    return_value = self.python_callable(*self.op_args, **self.op_kwargs)
  File "/home/fartash/Dev/ETL-boilerplate/app/transformer/twitter.py", line 21, in process
    raw_records = self.__fetch_tweets()
TypeError: __fetch_tweets() takes exactly 3 arguments (1 given)
ERROR 2017-03-11 09:57:26,007: root: handle_failure: 1327: __fetch_tweets() takes exactly 3 arguments (1 given): ()
ERROR 2017-03-11 09:58:03,637: root: handle_failure: 1286: syntax error at or near "]"
LINE 4:                 WHERE id=record[0]];
                                          ^
: ()
Traceback (most recent call last):
  File "/home/fartash/anaconda3/envs/Etl-boilerplate/lib/python2.7/site-packages/airflow/models.py", line 1245, in run
    result = task_copy.execute(context=context)
  File "/home/fartash/anaconda3/envs/Etl-boilerplate/lib/python2.7/site-packages/airflow/operators/python_operator.py", line 66, in execute
    return_value = self.python_callable(*self.op_args, **self.op_kwargs)
  File "/home/fartash/Dev/ETL-boilerplate/app/transformer/twitter.py", line 71, in process
    raise ex
ProgrammingError: syntax error at or near "]"
LINE 4:                 WHERE id=record[0]];
                                          ^

ERROR 2017-03-11 09:58:03,650: root: handle_failure: 1327: syntax error at or near "]"
LINE 4:                 WHERE id=record[0]];
                                          ^
: ()
ERROR 2017-03-11 09:58:42,110: root: handle_failure: 1286: column "record" does not exist
LINE 4:                 WHERE id=record[0];
                                 ^
: ()
Traceback (most recent call last):
  File "/home/fartash/anaconda3/envs/Etl-boilerplate/lib/python2.7/site-packages/airflow/models.py", line 1245, in run
    result = task_copy.execute(context=context)
  File "/home/fartash/anaconda3/envs/Etl-boilerplate/lib/python2.7/site-packages/airflow/operators/python_operator.py", line 66, in execute
    return_value = self.python_callable(*self.op_args, **self.op_kwargs)
  File "/home/fartash/Dev/ETL-boilerplate/app/transformer/twitter.py", line 71, in process
    raise ex
ProgrammingError: column "record" does not exist
LINE 4:                 WHERE id=record[0];
                                 ^

ERROR 2017-03-11 09:58:42,114: root: handle_failure: 1327: column "record" does not exist
LINE 4:                 WHERE id=record[0];
                                 ^
: ()
ERROR 2017-03-11 09:59:36,046: root: handle_failure: 1286: : ()
Traceback (most recent call last):
  File "/home/fartash/anaconda3/envs/Etl-boilerplate/lib/python2.7/site-packages/airflow/models.py", line 1245, in run
    result = task_copy.execute(context=context)
  File "/home/fartash/anaconda3/envs/Etl-boilerplate/lib/python2.7/site-packages/airflow/operators/python_operator.py", line 66, in execute
    return_value = self.python_callable(*self.op_args, **self.op_kwargs)
  File "/home/fartash/Dev/ETL-boilerplate/app/transformer/twitter.py", line 31, in process
    coordinates = self.__get_go_points(tweet['user']['location'])
  File "/home/fartash/Dev/ETL-boilerplate/app/transformer/twitter.py", line 101, in __get_go_points
    res = self.googlemaps_api.search(address.strip(string.punctuation + ' ')).first()
  File "/home/fartash/anaconda3/envs/Etl-boilerplate/lib/python2.7/site-packages/geolocation/main.py", line 18, in search
    return self.geocode.search(location, lat, lng)
  File "/home/fartash/anaconda3/envs/Etl-boilerplate/lib/python2.7/site-packages/geolocation/geocode/main.py", line 48, in search
    data = self.client.get_data(address=address, latitude=latitude, longitude=longitude)
  File "/home/fartash/anaconda3/envs/Etl-boilerplate/lib/python2.7/site-packages/geolocation/geocode/client.py", line 40, in get_data
    return self.send_data(self.API_URL, self.query_parameters)
  File "/home/fartash/anaconda3/envs/Etl-boilerplate/lib/python2.7/site-packages/geolocation/client.py", line 22, in send_data
    response = requests.get(url, params=params)
  File "/home/fartash/anaconda3/envs/Etl-boilerplate/lib/python2.7/site-packages/requests/api.py", line 70, in get
    return request('get', url, params=params, **kwargs)
  File "/home/fartash/anaconda3/envs/Etl-boilerplate/lib/python2.7/site-packages/requests/api.py", line 56, in request
    return session.request(method=method, url=url, **kwargs)
  File "/home/fartash/anaconda3/envs/Etl-boilerplate/lib/python2.7/site-packages/requests/sessions.py", line 488, in request
    resp = self.send(prep, **send_kwargs)
  File "/home/fartash/anaconda3/envs/Etl-boilerplate/lib/python2.7/site-packages/requests/sessions.py", line 609, in send
    r = adapter.send(request, **kwargs)
  File "/home/fartash/anaconda3/envs/Etl-boilerplate/lib/python2.7/site-packages/requests/adapters.py", line 423, in send
    timeout=timeout
  File "/home/fartash/anaconda3/envs/Etl-boilerplate/lib/python2.7/site-packages/requests/packages/urllib3/connectionpool.py", line 600, in urlopen
    chunked=chunked)
  File "/home/fartash/anaconda3/envs/Etl-boilerplate/lib/python2.7/site-packages/requests/packages/urllib3/connectionpool.py", line 345, in _make_request
    self._validate_conn(conn)
  File "/home/fartash/anaconda3/envs/Etl-boilerplate/lib/python2.7/site-packages/requests/packages/urllib3/connectionpool.py", line 844, in _validate_conn
    conn.connect()
  File "/home/fartash/anaconda3/envs/Etl-boilerplate/lib/python2.7/site-packages/requests/packages/urllib3/connection.py", line 284, in connect
    conn = self._new_conn()
  File "/home/fartash/anaconda3/envs/Etl-boilerplate/lib/python2.7/site-packages/requests/packages/urllib3/connection.py", line 141, in _new_conn
    (self.host, self.port), self.timeout, **extra_kw)
  File "/home/fartash/anaconda3/envs/Etl-boilerplate/lib/python2.7/site-packages/requests/packages/urllib3/util/connection.py", line 60, in create_connection
    for res in socket.getaddrinfo(host, port, family, socket.SOCK_STREAM):
KeyboardInterrupt
ERROR 2017-03-11 09:59:36,057: root: handle_failure: 1327: : ()
ERROR 2017-03-11 10:08:36,104: root: handle_failure: 1286: : ()
Traceback (most recent call last):
  File "/home/fartash/anaconda3/envs/Etl-boilerplate/lib/python2.7/site-packages/airflow/models.py", line 1245, in run
    result = task_copy.execute(context=context)
  File "/home/fartash/anaconda3/envs/Etl-boilerplate/lib/python2.7/site-packages/airflow/operators/python_operator.py", line 66, in execute
    return_value = self.python_callable(*self.op_args, **self.op_kwargs)
  File "/home/fartash/Dev/ETL-boilerplate/app/transformer/twitter.py", line 21, in process
    raw_records = self.__fetch_tweets()
  File "/home/fartash/Dev/ETL-boilerplate/app/transformer/twitter.py", line 84, in __fetch_tweets
    return cur_db_lake.fetchall()
  File "/home/fartash/anaconda3/envs/Etl-boilerplate/lib/python2.7/site-packages/psycopg2/_json.py", line 181, in typecast_json
    return loads(s)
  File "/home/fartash/anaconda3/envs/Etl-boilerplate/lib/python2.7/json/__init__.py", line 339, in loads
    return _default_decoder.decode(s)
  File "/home/fartash/anaconda3/envs/Etl-boilerplate/lib/python2.7/json/decoder.py", line 364, in decode
    obj, end = self.raw_decode(s, idx=_w(s, 0).end())
  File "/home/fartash/anaconda3/envs/Etl-boilerplate/lib/python2.7/json/decoder.py", line 380, in raw_decode
    obj, end = self.scan_once(s, idx)
KeyboardInterrupt
ERROR 2017-03-11 10:08:36,112: root: handle_failure: 1327: : ()
ERROR 2017-03-11 10:08:44,032: root: handle_failure: 1286: __fetch_tweets() takes exactly 1 argument (3 given): ()
Traceback (most recent call last):
  File "/home/fartash/anaconda3/envs/Etl-boilerplate/lib/python2.7/site-packages/airflow/models.py", line 1245, in run
    result = task_copy.execute(context=context)
  File "/home/fartash/anaconda3/envs/Etl-boilerplate/lib/python2.7/site-packages/airflow/operators/python_operator.py", line 66, in execute
    return_value = self.python_callable(*self.op_args, **self.op_kwargs)
  File "/home/fartash/Dev/ETL-boilerplate/app/loader/twitter.py", line 16, in load_into_elastic
    docs = self.__fetch_tweets(ds - kwargs.get('interval'), ds)
TypeError: __fetch_tweets() takes exactly 1 argument (3 given)
ERROR 2017-03-11 10:08:44,033: root: handle_failure: 1327: __fetch_tweets() takes exactly 1 argument (3 given): ()
ERROR 2017-03-11 10:11:55,472: root: handle_failure: 1286: Successful parsed but returned no results.: ()
Traceback (most recent call last):
  File "/home/fartash/anaconda3/envs/Etl-boilerplate/lib/python2.7/site-packages/airflow/models.py", line 1245, in run
    result = task_copy.execute(context=context)
  File "/home/fartash/anaconda3/envs/Etl-boilerplate/lib/python2.7/site-packages/airflow/operators/python_operator.py", line 66, in execute
    return_value = self.python_callable(*self.op_args, **self.op_kwargs)
  File "/home/fartash/Dev/ETL-boilerplate/app/transformer/twitter.py", line 31, in process
    coordinates = self.__get_go_points(tweet['user']['location'])
  File "/home/fartash/Dev/ETL-boilerplate/app/transformer/twitter.py", line 101, in __get_go_points
    res = self.googlemaps_api.search(address.strip(string.punctuation + ' ')).first()
  File "/home/fartash/anaconda3/envs/Etl-boilerplate/lib/python2.7/site-packages/geolocation/main.py", line 18, in search
    return self.geocode.search(location, lat, lng)
  File "/home/fartash/anaconda3/envs/Etl-boilerplate/lib/python2.7/site-packages/geolocation/geocode/main.py", line 48, in search
    data = self.client.get_data(address=address, latitude=latitude, longitude=longitude)
  File "/home/fartash/anaconda3/envs/Etl-boilerplate/lib/python2.7/site-packages/geolocation/geocode/client.py", line 40, in get_data
    return self.send_data(self.API_URL, self.query_parameters)
  File "/home/fartash/anaconda3/envs/Etl-boilerplate/lib/python2.7/site-packages/geolocation/client.py", line 23, in send_data
    self.validator(response)
  File "/home/fartash/anaconda3/envs/Etl-boilerplate/lib/python2.7/site-packages/geolocation/validators.py", line 28, in __init__
    self.validation(response)
  File "/home/fartash/anaconda3/envs/Etl-boilerplate/lib/python2.7/site-packages/geolocation/validators.py", line 55, in validation
    self.validate_google_status(response)
  File "/home/fartash/anaconda3/envs/Etl-boilerplate/lib/python2.7/site-packages/geolocation/validators.py", line 46, in validate_google_status
    raise ApiClientException(message)
ApiClientException: Successful parsed but returned no results.
ERROR 2017-03-11 10:11:55,503: root: handle_failure: 1327: Successful parsed but returned no results.: ()
ERROR 2017-03-11 10:12:13,060: root: handle_failure: 1286: Successful parsed but returned no results.: ()
Traceback (most recent call last):
  File "/home/fartash/anaconda3/envs/Etl-boilerplate/lib/python2.7/site-packages/airflow/models.py", line 1245, in run
    result = task_copy.execute(context=context)
  File "/home/fartash/anaconda3/envs/Etl-boilerplate/lib/python2.7/site-packages/airflow/operators/python_operator.py", line 66, in execute
    return_value = self.python_callable(*self.op_args, **self.op_kwargs)
  File "/home/fartash/Dev/ETL-boilerplate/app/transformer/twitter.py", line 31, in process
    coordinates = self.__get_go_points(tweet['user']['location'])
  File "/home/fartash/Dev/ETL-boilerplate/app/transformer/twitter.py", line 101, in __get_go_points
    res = self.googlemaps_api.search(address.strip(string.punctuation + ' ')).first()
  File "/home/fartash/anaconda3/envs/Etl-boilerplate/lib/python2.7/site-packages/geolocation/main.py", line 18, in search
    return self.geocode.search(location, lat, lng)
  File "/home/fartash/anaconda3/envs/Etl-boilerplate/lib/python2.7/site-packages/geolocation/geocode/main.py", line 48, in search
    data = self.client.get_data(address=address, latitude=latitude, longitude=longitude)
  File "/home/fartash/anaconda3/envs/Etl-boilerplate/lib/python2.7/site-packages/geolocation/geocode/client.py", line 40, in get_data
    return self.send_data(self.API_URL, self.query_parameters)
  File "/home/fartash/anaconda3/envs/Etl-boilerplate/lib/python2.7/site-packages/geolocation/client.py", line 23, in send_data
    self.validator(response)
  File "/home/fartash/anaconda3/envs/Etl-boilerplate/lib/python2.7/site-packages/geolocation/validators.py", line 28, in __init__
    self.validation(response)
  File "/home/fartash/anaconda3/envs/Etl-boilerplate/lib/python2.7/site-packages/geolocation/validators.py", line 55, in validation
    self.validate_google_status(response)
  File "/home/fartash/anaconda3/envs/Etl-boilerplate/lib/python2.7/site-packages/geolocation/validators.py", line 46, in validate_google_status
    raise ApiClientException(message)
ApiClientException: Successful parsed but returned no results.
ERROR 2017-03-11 10:12:13,082: root: handle_failure: 1327: Successful parsed but returned no results.: ()
ERROR 2017-03-11 10:12:32,710: root: handle_failure: 1286: Successful parsed but returned no results.: ()
Traceback (most recent call last):
  File "/home/fartash/anaconda3/envs/Etl-boilerplate/lib/python2.7/site-packages/airflow/models.py", line 1245, in run
    result = task_copy.execute(context=context)
  File "/home/fartash/anaconda3/envs/Etl-boilerplate/lib/python2.7/site-packages/airflow/operators/python_operator.py", line 66, in execute
    return_value = self.python_callable(*self.op_args, **self.op_kwargs)
  File "/home/fartash/Dev/ETL-boilerplate/app/transformer/twitter.py", line 31, in process
    coordinates = self.__get_go_points(tweet['user']['location'])
  File "/home/fartash/Dev/ETL-boilerplate/app/transformer/twitter.py", line 101, in __get_go_points
    res = self.googlemaps_api.search(address.strip(string.punctuation + ' ')).first()
  File "/home/fartash/anaconda3/envs/Etl-boilerplate/lib/python2.7/site-packages/geolocation/main.py", line 18, in search
    return self.geocode.search(location, lat, lng)
  File "/home/fartash/anaconda3/envs/Etl-boilerplate/lib/python2.7/site-packages/geolocation/geocode/main.py", line 48, in search
    data = self.client.get_data(address=address, latitude=latitude, longitude=longitude)
  File "/home/fartash/anaconda3/envs/Etl-boilerplate/lib/python2.7/site-packages/geolocation/geocode/client.py", line 40, in get_data
    return self.send_data(self.API_URL, self.query_parameters)
  File "/home/fartash/anaconda3/envs/Etl-boilerplate/lib/python2.7/site-packages/geolocation/client.py", line 23, in send_data
    self.validator(response)
  File "/home/fartash/anaconda3/envs/Etl-boilerplate/lib/python2.7/site-packages/geolocation/validators.py", line 28, in __init__
    self.validation(response)
  File "/home/fartash/anaconda3/envs/Etl-boilerplate/lib/python2.7/site-packages/geolocation/validators.py", line 55, in validation
    self.validate_google_status(response)
  File "/home/fartash/anaconda3/envs/Etl-boilerplate/lib/python2.7/site-packages/geolocation/validators.py", line 46, in validate_google_status
    raise ApiClientException(message)
ApiClientException: Successful parsed but returned no results.
ERROR 2017-03-11 10:12:32,726: root: handle_failure: 1327: Successful parsed but returned no results.: ()
ERROR 2017-03-11 10:12:44,453: root: handle_failure: 1286: : ()
Traceback (most recent call last):
  File "/home/fartash/anaconda3/envs/Etl-boilerplate/lib/python2.7/site-packages/airflow/models.py", line 1245, in run
    result = task_copy.execute(context=context)
  File "/home/fartash/anaconda3/envs/Etl-boilerplate/lib/python2.7/site-packages/airflow/operators/python_operator.py", line 66, in execute
    return_value = self.python_callable(*self.op_args, **self.op_kwargs)
  File "/home/fartash/Dev/ETL-boilerplate/app/transformer/twitter.py", line 21, in process
    raw_records = self.__fetch_tweets()
  File "/home/fartash/Dev/ETL-boilerplate/app/transformer/twitter.py", line 84, in __fetch_tweets
    return cur_db_lake.fetchall()
  File "/home/fartash/anaconda3/envs/Etl-boilerplate/lib/python2.7/site-packages/psycopg2/_json.py", line 181, in typecast_json
    return loads(s)
  File "/home/fartash/anaconda3/envs/Etl-boilerplate/lib/python2.7/json/__init__.py", line 339, in loads
    return _default_decoder.decode(s)
  File "/home/fartash/anaconda3/envs/Etl-boilerplate/lib/python2.7/json/decoder.py", line 364, in decode
    obj, end = self.raw_decode(s, idx=_w(s, 0).end())
  File "/home/fartash/anaconda3/envs/Etl-boilerplate/lib/python2.7/json/decoder.py", line 380, in raw_decode
    obj, end = self.scan_once(s, idx)
KeyboardInterrupt
ERROR 2017-03-11 10:12:44,484: root: handle_failure: 1327: : ()
ERROR 2017-03-11 10:14:22,002: root: handle_failure: 1286: Successful parsed but returned no results.: ()
Traceback (most recent call last):
  File "/home/fartash/anaconda3/envs/Etl-boilerplate/lib/python2.7/site-packages/airflow/models.py", line 1245, in run
    result = task_copy.execute(context=context)
  File "/home/fartash/anaconda3/envs/Etl-boilerplate/lib/python2.7/site-packages/airflow/operators/python_operator.py", line 66, in execute
    return_value = self.python_callable(*self.op_args, **self.op_kwargs)
  File "/home/fartash/Dev/ETL-boilerplate/app/transformer/twitter.py", line 31, in process
    coordinates = self.__get_go_points(tweet['user']['location'])
  File "/home/fartash/Dev/ETL-boilerplate/app/transformer/twitter.py", line 101, in __get_go_points
    res = self.googlemaps_api.search(address.strip(string.punctuation + ' ')).first()
  File "/home/fartash/anaconda3/envs/Etl-boilerplate/lib/python2.7/site-packages/geolocation/main.py", line 18, in search
    return self.geocode.search(location, lat, lng)
  File "/home/fartash/anaconda3/envs/Etl-boilerplate/lib/python2.7/site-packages/geolocation/geocode/main.py", line 48, in search
    data = self.client.get_data(address=address, latitude=latitude, longitude=longitude)
  File "/home/fartash/anaconda3/envs/Etl-boilerplate/lib/python2.7/site-packages/geolocation/geocode/client.py", line 40, in get_data
    return self.send_data(self.API_URL, self.query_parameters)
  File "/home/fartash/anaconda3/envs/Etl-boilerplate/lib/python2.7/site-packages/geolocation/client.py", line 23, in send_data
    self.validator(response)
  File "/home/fartash/anaconda3/envs/Etl-boilerplate/lib/python2.7/site-packages/geolocation/validators.py", line 28, in __init__
    self.validation(response)
  File "/home/fartash/anaconda3/envs/Etl-boilerplate/lib/python2.7/site-packages/geolocation/validators.py", line 55, in validation
    self.validate_google_status(response)
  File "/home/fartash/anaconda3/envs/Etl-boilerplate/lib/python2.7/site-packages/geolocation/validators.py", line 46, in validate_google_status
    raise ApiClientException(message)
ApiClientException: Successful parsed but returned no results.
ERROR 2017-03-11 10:14:22,076: root: handle_failure: 1327: Successful parsed but returned no results.: ()
ERROR 2017-03-11 10:14:33,030: root: handle_failure: 1286: Successful parsed but returned no results.: ()
Traceback (most recent call last):
  File "/home/fartash/anaconda3/envs/Etl-boilerplate/lib/python2.7/site-packages/airflow/models.py", line 1245, in run
    result = task_copy.execute(context=context)
  File "/home/fartash/anaconda3/envs/Etl-boilerplate/lib/python2.7/site-packages/airflow/operators/python_operator.py", line 66, in execute
    return_value = self.python_callable(*self.op_args, **self.op_kwargs)
  File "/home/fartash/Dev/ETL-boilerplate/app/transformer/twitter.py", line 31, in process
    coordinates = self.__get_go_points(tweet['user']['location'])
  File "/home/fartash/Dev/ETL-boilerplate/app/transformer/twitter.py", line 101, in __get_go_points
    res = self.googlemaps_api.search(address.strip(string.punctuation + ' ')).first()
  File "/home/fartash/anaconda3/envs/Etl-boilerplate/lib/python2.7/site-packages/geolocation/main.py", line 18, in search
    return self.geocode.search(location, lat, lng)
  File "/home/fartash/anaconda3/envs/Etl-boilerplate/lib/python2.7/site-packages/geolocation/geocode/main.py", line 48, in search
    data = self.client.get_data(address=address, latitude=latitude, longitude=longitude)
  File "/home/fartash/anaconda3/envs/Etl-boilerplate/lib/python2.7/site-packages/geolocation/geocode/client.py", line 40, in get_data
    return self.send_data(self.API_URL, self.query_parameters)
  File "/home/fartash/anaconda3/envs/Etl-boilerplate/lib/python2.7/site-packages/geolocation/client.py", line 23, in send_data
    self.validator(response)
  File "/home/fartash/anaconda3/envs/Etl-boilerplate/lib/python2.7/site-packages/geolocation/validators.py", line 28, in __init__
    self.validation(response)
  File "/home/fartash/anaconda3/envs/Etl-boilerplate/lib/python2.7/site-packages/geolocation/validators.py", line 55, in validation
    self.validate_google_status(response)
  File "/home/fartash/anaconda3/envs/Etl-boilerplate/lib/python2.7/site-packages/geolocation/validators.py", line 46, in validate_google_status
    raise ApiClientException(message)
ApiClientException: Successful parsed but returned no results.
ERROR 2017-03-11 10:14:33,045: root: handle_failure: 1327: Successful parsed but returned no results.: ()
ERROR 2017-03-11 10:14:45,001: root: handle_failure: 1286: Successful parsed but returned no results.: ()
Traceback (most recent call last):
  File "/home/fartash/anaconda3/envs/Etl-boilerplate/lib/python2.7/site-packages/airflow/models.py", line 1245, in run
    result = task_copy.execute(context=context)
  File "/home/fartash/anaconda3/envs/Etl-boilerplate/lib/python2.7/site-packages/airflow/operators/python_operator.py", line 66, in execute
    return_value = self.python_callable(*self.op_args, **self.op_kwargs)
  File "/home/fartash/Dev/ETL-boilerplate/app/transformer/twitter.py", line 31, in process
    coordinates = self.__get_go_points(tweet['user']['location'])
  File "/home/fartash/Dev/ETL-boilerplate/app/transformer/twitter.py", line 101, in __get_go_points
    res = self.googlemaps_api.search(address.strip(string.punctuation + ' ')).first()
  File "/home/fartash/anaconda3/envs/Etl-boilerplate/lib/python2.7/site-packages/geolocation/main.py", line 18, in search
    return self.geocode.search(location, lat, lng)
  File "/home/fartash/anaconda3/envs/Etl-boilerplate/lib/python2.7/site-packages/geolocation/geocode/main.py", line 48, in search
    data = self.client.get_data(address=address, latitude=latitude, longitude=longitude)
  File "/home/fartash/anaconda3/envs/Etl-boilerplate/lib/python2.7/site-packages/geolocation/geocode/client.py", line 40, in get_data
    return self.send_data(self.API_URL, self.query_parameters)
  File "/home/fartash/anaconda3/envs/Etl-boilerplate/lib/python2.7/site-packages/geolocation/client.py", line 23, in send_data
    self.validator(response)
  File "/home/fartash/anaconda3/envs/Etl-boilerplate/lib/python2.7/site-packages/geolocation/validators.py", line 28, in __init__
    self.validation(response)
  File "/home/fartash/anaconda3/envs/Etl-boilerplate/lib/python2.7/site-packages/geolocation/validators.py", line 55, in validation
    self.validate_google_status(response)
  File "/home/fartash/anaconda3/envs/Etl-boilerplate/lib/python2.7/site-packages/geolocation/validators.py", line 46, in validate_google_status
    raise ApiClientException(message)
ApiClientException: Successful parsed but returned no results.
ERROR 2017-03-11 10:14:45,106: root: handle_failure: 1327: Successful parsed but returned no results.: ()
ERROR 2017-03-11 10:14:57,550: root: handle_failure: 1286: Successful parsed but returned no results.: ()
Traceback (most recent call last):
  File "/home/fartash/anaconda3/envs/Etl-boilerplate/lib/python2.7/site-packages/airflow/models.py", line 1245, in run
    result = task_copy.execute(context=context)
  File "/home/fartash/anaconda3/envs/Etl-boilerplate/lib/python2.7/site-packages/airflow/operators/python_operator.py", line 66, in execute
    return_value = self.python_callable(*self.op_args, **self.op_kwargs)
  File "/home/fartash/Dev/ETL-boilerplate/app/transformer/twitter.py", line 31, in process
    coordinates = self.__get_go_points(tweet['user']['location'])
  File "/home/fartash/Dev/ETL-boilerplate/app/transformer/twitter.py", line 101, in __get_go_points
    res = self.googlemaps_api.search(address.strip(string.punctuation + ' ')).first()
  File "/home/fartash/anaconda3/envs/Etl-boilerplate/lib/python2.7/site-packages/geolocation/main.py", line 18, in search
    return self.geocode.search(location, lat, lng)
  File "/home/fartash/anaconda3/envs/Etl-boilerplate/lib/python2.7/site-packages/geolocation/geocode/main.py", line 48, in search
    data = self.client.get_data(address=address, latitude=latitude, longitude=longitude)
  File "/home/fartash/anaconda3/envs/Etl-boilerplate/lib/python2.7/site-packages/geolocation/geocode/client.py", line 40, in get_data
    return self.send_data(self.API_URL, self.query_parameters)
  File "/home/fartash/anaconda3/envs/Etl-boilerplate/lib/python2.7/site-packages/geolocation/client.py", line 23, in send_data
    self.validator(response)
  File "/home/fartash/anaconda3/envs/Etl-boilerplate/lib/python2.7/site-packages/geolocation/validators.py", line 28, in __init__
    self.validation(response)
  File "/home/fartash/anaconda3/envs/Etl-boilerplate/lib/python2.7/site-packages/geolocation/validators.py", line 55, in validation
    self.validate_google_status(response)
  File "/home/fartash/anaconda3/envs/Etl-boilerplate/lib/python2.7/site-packages/geolocation/validators.py", line 46, in validate_google_status
    raise ApiClientException(message)
ApiClientException: Successful parsed but returned no results.
ERROR 2017-03-11 10:14:57,576: root: handle_failure: 1327: Successful parsed but returned no results.: ()
ERROR 2017-03-11 10:15:11,328: root: handle_failure: 1286: Successful parsed but returned no results.: ()
Traceback (most recent call last):
  File "/home/fartash/anaconda3/envs/Etl-boilerplate/lib/python2.7/site-packages/airflow/models.py", line 1245, in run
    result = task_copy.execute(context=context)
  File "/home/fartash/anaconda3/envs/Etl-boilerplate/lib/python2.7/site-packages/airflow/operators/python_operator.py", line 66, in execute
    return_value = self.python_callable(*self.op_args, **self.op_kwargs)
  File "/home/fartash/Dev/ETL-boilerplate/app/transformer/twitter.py", line 31, in process
    coordinates = self.__get_go_points(tweet['user']['location'])
  File "/home/fartash/Dev/ETL-boilerplate/app/transformer/twitter.py", line 101, in __get_go_points
    res = self.googlemaps_api.search(address.strip(string.punctuation + ' ')).first()
  File "/home/fartash/anaconda3/envs/Etl-boilerplate/lib/python2.7/site-packages/geolocation/main.py", line 18, in search
    return self.geocode.search(location, lat, lng)
  File "/home/fartash/anaconda3/envs/Etl-boilerplate/lib/python2.7/site-packages/geolocation/geocode/main.py", line 48, in search
    data = self.client.get_data(address=address, latitude=latitude, longitude=longitude)
  File "/home/fartash/anaconda3/envs/Etl-boilerplate/lib/python2.7/site-packages/geolocation/geocode/client.py", line 40, in get_data
    return self.send_data(self.API_URL, self.query_parameters)
  File "/home/fartash/anaconda3/envs/Etl-boilerplate/lib/python2.7/site-packages/geolocation/client.py", line 23, in send_data
    self.validator(response)
  File "/home/fartash/anaconda3/envs/Etl-boilerplate/lib/python2.7/site-packages/geolocation/validators.py", line 28, in __init__
    self.validation(response)
  File "/home/fartash/anaconda3/envs/Etl-boilerplate/lib/python2.7/site-packages/geolocation/validators.py", line 55, in validation
    self.validate_google_status(response)
  File "/home/fartash/anaconda3/envs/Etl-boilerplate/lib/python2.7/site-packages/geolocation/validators.py", line 46, in validate_google_status
    raise ApiClientException(message)
ApiClientException: Successful parsed but returned no results.
ERROR 2017-03-11 10:15:11,348: root: handle_failure: 1327: Successful parsed but returned no results.: ()
ERROR 2017-03-11 10:15:25,685: root: handle_failure: 1286: Successful parsed but returned no results.: ()
Traceback (most recent call last):
  File "/home/fartash/anaconda3/envs/Etl-boilerplate/lib/python2.7/site-packages/airflow/models.py", line 1245, in run
    result = task_copy.execute(context=context)
  File "/home/fartash/anaconda3/envs/Etl-boilerplate/lib/python2.7/site-packages/airflow/operators/python_operator.py", line 66, in execute
    return_value = self.python_callable(*self.op_args, **self.op_kwargs)
  File "/home/fartash/Dev/ETL-boilerplate/app/transformer/twitter.py", line 31, in process
    coordinates = self.__get_go_points(tweet['user']['location'])
  File "/home/fartash/Dev/ETL-boilerplate/app/transformer/twitter.py", line 101, in __get_go_points
    res = self.googlemaps_api.search(address.strip(string.punctuation + ' ')).first()
  File "/home/fartash/anaconda3/envs/Etl-boilerplate/lib/python2.7/site-packages/geolocation/main.py", line 18, in search
    return self.geocode.search(location, lat, lng)
  File "/home/fartash/anaconda3/envs/Etl-boilerplate/lib/python2.7/site-packages/geolocation/geocode/main.py", line 48, in search
    data = self.client.get_data(address=address, latitude=latitude, longitude=longitude)
  File "/home/fartash/anaconda3/envs/Etl-boilerplate/lib/python2.7/site-packages/geolocation/geocode/client.py", line 40, in get_data
    return self.send_data(self.API_URL, self.query_parameters)
  File "/home/fartash/anaconda3/envs/Etl-boilerplate/lib/python2.7/site-packages/geolocation/client.py", line 23, in send_data
    self.validator(response)
  File "/home/fartash/anaconda3/envs/Etl-boilerplate/lib/python2.7/site-packages/geolocation/validators.py", line 28, in __init__
    self.validation(response)
  File "/home/fartash/anaconda3/envs/Etl-boilerplate/lib/python2.7/site-packages/geolocation/validators.py", line 55, in validation
    self.validate_google_status(response)
  File "/home/fartash/anaconda3/envs/Etl-boilerplate/lib/python2.7/site-packages/geolocation/validators.py", line 46, in validate_google_status
    raise ApiClientException(message)
ApiClientException: Successful parsed but returned no results.
ERROR 2017-03-11 10:15:25,705: root: handle_failure: 1327: Successful parsed but returned no results.: ()
ERROR 2017-03-11 10:15:37,162: root: handle_failure: 1286: Successful parsed but returned no results.: ()
Traceback (most recent call last):
  File "/home/fartash/anaconda3/envs/Etl-boilerplate/lib/python2.7/site-packages/airflow/models.py", line 1245, in run
    result = task_copy.execute(context=context)
  File "/home/fartash/anaconda3/envs/Etl-boilerplate/lib/python2.7/site-packages/airflow/operators/python_operator.py", line 66, in execute
    return_value = self.python_callable(*self.op_args, **self.op_kwargs)
  File "/home/fartash/Dev/ETL-boilerplate/app/transformer/twitter.py", line 31, in process
    coordinates = self.__get_go_points(tweet['user']['location'])
  File "/home/fartash/Dev/ETL-boilerplate/app/transformer/twitter.py", line 101, in __get_go_points
    res = self.googlemaps_api.search(address.strip(string.punctuation + ' ')).first()
  File "/home/fartash/anaconda3/envs/Etl-boilerplate/lib/python2.7/site-packages/geolocation/main.py", line 18, in search
    return self.geocode.search(location, lat, lng)
  File "/home/fartash/anaconda3/envs/Etl-boilerplate/lib/python2.7/site-packages/geolocation/geocode/main.py", line 48, in search
    data = self.client.get_data(address=address, latitude=latitude, longitude=longitude)
  File "/home/fartash/anaconda3/envs/Etl-boilerplate/lib/python2.7/site-packages/geolocation/geocode/client.py", line 40, in get_data
    return self.send_data(self.API_URL, self.query_parameters)
  File "/home/fartash/anaconda3/envs/Etl-boilerplate/lib/python2.7/site-packages/geolocation/client.py", line 23, in send_data
    self.validator(response)
  File "/home/fartash/anaconda3/envs/Etl-boilerplate/lib/python2.7/site-packages/geolocation/validators.py", line 28, in __init__
    self.validation(response)
  File "/home/fartash/anaconda3/envs/Etl-boilerplate/lib/python2.7/site-packages/geolocation/validators.py", line 55, in validation
    self.validate_google_status(response)
  File "/home/fartash/anaconda3/envs/Etl-boilerplate/lib/python2.7/site-packages/geolocation/validators.py", line 46, in validate_google_status
    raise ApiClientException(message)
ApiClientException: Successful parsed but returned no results.
ERROR 2017-03-11 10:15:37,186: root: handle_failure: 1327: Successful parsed but returned no results.: ()
ERROR 2017-03-11 10:15:51,842: root: handle_failure: 1286: Successful parsed but returned no results.: ()
Traceback (most recent call last):
  File "/home/fartash/anaconda3/envs/Etl-boilerplate/lib/python2.7/site-packages/airflow/models.py", line 1245, in run
    result = task_copy.execute(context=context)
  File "/home/fartash/anaconda3/envs/Etl-boilerplate/lib/python2.7/site-packages/airflow/operators/python_operator.py", line 66, in execute
    return_value = self.python_callable(*self.op_args, **self.op_kwargs)
  File "/home/fartash/Dev/ETL-boilerplate/app/transformer/twitter.py", line 31, in process
    coordinates = self.__get_go_points(tweet['user']['location'])
  File "/home/fartash/Dev/ETL-boilerplate/app/transformer/twitter.py", line 101, in __get_go_points
    res = self.googlemaps_api.search(address.strip(string.punctuation + ' ')).first()
  File "/home/fartash/anaconda3/envs/Etl-boilerplate/lib/python2.7/site-packages/geolocation/main.py", line 18, in search
    return self.geocode.search(location, lat, lng)
  File "/home/fartash/anaconda3/envs/Etl-boilerplate/lib/python2.7/site-packages/geolocation/geocode/main.py", line 48, in search
    data = self.client.get_data(address=address, latitude=latitude, longitude=longitude)
  File "/home/fartash/anaconda3/envs/Etl-boilerplate/lib/python2.7/site-packages/geolocation/geocode/client.py", line 40, in get_data
    return self.send_data(self.API_URL, self.query_parameters)
  File "/home/fartash/anaconda3/envs/Etl-boilerplate/lib/python2.7/site-packages/geolocation/client.py", line 23, in send_data
    self.validator(response)
  File "/home/fartash/anaconda3/envs/Etl-boilerplate/lib/python2.7/site-packages/geolocation/validators.py", line 28, in __init__
    self.validation(response)
  File "/home/fartash/anaconda3/envs/Etl-boilerplate/lib/python2.7/site-packages/geolocation/validators.py", line 55, in validation
    self.validate_google_status(response)
  File "/home/fartash/anaconda3/envs/Etl-boilerplate/lib/python2.7/site-packages/geolocation/validators.py", line 46, in validate_google_status
    raise ApiClientException(message)
ApiClientException: Successful parsed but returned no results.
ERROR 2017-03-11 10:15:51,863: root: handle_failure: 1327: Successful parsed but returned no results.: ()
ERROR 2017-03-11 10:16:09,272: root: handle_failure: 1286: Successful parsed but returned no results.: ()
Traceback (most recent call last):
  File "/home/fartash/anaconda3/envs/Etl-boilerplate/lib/python2.7/site-packages/airflow/models.py", line 1245, in run
    result = task_copy.execute(context=context)
  File "/home/fartash/anaconda3/envs/Etl-boilerplate/lib/python2.7/site-packages/airflow/operators/python_operator.py", line 66, in execute
    return_value = self.python_callable(*self.op_args, **self.op_kwargs)
  File "/home/fartash/Dev/ETL-boilerplate/app/transformer/twitter.py", line 31, in process
    coordinates = self.__get_go_points(tweet['user']['location'])
  File "/home/fartash/Dev/ETL-boilerplate/app/transformer/twitter.py", line 101, in __get_go_points
    res = self.googlemaps_api.search(address.strip(string.punctuation + ' ')).first()
  File "/home/fartash/anaconda3/envs/Etl-boilerplate/lib/python2.7/site-packages/geolocation/main.py", line 18, in search
    return self.geocode.search(location, lat, lng)
  File "/home/fartash/anaconda3/envs/Etl-boilerplate/lib/python2.7/site-packages/geolocation/geocode/main.py", line 48, in search
    data = self.client.get_data(address=address, latitude=latitude, longitude=longitude)
  File "/home/fartash/anaconda3/envs/Etl-boilerplate/lib/python2.7/site-packages/geolocation/geocode/client.py", line 40, in get_data
    return self.send_data(self.API_URL, self.query_parameters)
  File "/home/fartash/anaconda3/envs/Etl-boilerplate/lib/python2.7/site-packages/geolocation/client.py", line 23, in send_data
    self.validator(response)
  File "/home/fartash/anaconda3/envs/Etl-boilerplate/lib/python2.7/site-packages/geolocation/validators.py", line 28, in __init__
    self.validation(response)
  File "/home/fartash/anaconda3/envs/Etl-boilerplate/lib/python2.7/site-packages/geolocation/validators.py", line 55, in validation
    self.validate_google_status(response)
  File "/home/fartash/anaconda3/envs/Etl-boilerplate/lib/python2.7/site-packages/geolocation/validators.py", line 46, in validate_google_status
    raise ApiClientException(message)
ApiClientException: Successful parsed but returned no results.
ERROR 2017-03-11 10:16:09,293: root: handle_failure: 1327: Successful parsed but returned no results.: ()
ERROR 2017-03-11 10:16:22,298: root: handle_failure: 1286: Successful parsed but returned no results.: ()
Traceback (most recent call last):
  File "/home/fartash/anaconda3/envs/Etl-boilerplate/lib/python2.7/site-packages/airflow/models.py", line 1245, in run
    result = task_copy.execute(context=context)
  File "/home/fartash/anaconda3/envs/Etl-boilerplate/lib/python2.7/site-packages/airflow/operators/python_operator.py", line 66, in execute
    return_value = self.python_callable(*self.op_args, **self.op_kwargs)
  File "/home/fartash/Dev/ETL-boilerplate/app/transformer/twitter.py", line 31, in process
    coordinates = self.__get_go_points(tweet['user']['location'])
  File "/home/fartash/Dev/ETL-boilerplate/app/transformer/twitter.py", line 101, in __get_go_points
    res = self.googlemaps_api.search(address.strip(string.punctuation + ' ')).first()
  File "/home/fartash/anaconda3/envs/Etl-boilerplate/lib/python2.7/site-packages/geolocation/main.py", line 18, in search
    return self.geocode.search(location, lat, lng)
  File "/home/fartash/anaconda3/envs/Etl-boilerplate/lib/python2.7/site-packages/geolocation/geocode/main.py", line 48, in search
    data = self.client.get_data(address=address, latitude=latitude, longitude=longitude)
  File "/home/fartash/anaconda3/envs/Etl-boilerplate/lib/python2.7/site-packages/geolocation/geocode/client.py", line 40, in get_data
    return self.send_data(self.API_URL, self.query_parameters)
  File "/home/fartash/anaconda3/envs/Etl-boilerplate/lib/python2.7/site-packages/geolocation/client.py", line 23, in send_data
    self.validator(response)
  File "/home/fartash/anaconda3/envs/Etl-boilerplate/lib/python2.7/site-packages/geolocation/validators.py", line 28, in __init__
    self.validation(response)
  File "/home/fartash/anaconda3/envs/Etl-boilerplate/lib/python2.7/site-packages/geolocation/validators.py", line 55, in validation
    self.validate_google_status(response)
  File "/home/fartash/anaconda3/envs/Etl-boilerplate/lib/python2.7/site-packages/geolocation/validators.py", line 46, in validate_google_status
    raise ApiClientException(message)
ApiClientException: Successful parsed but returned no results.
ERROR 2017-03-11 10:16:22,316: root: handle_failure: 1327: Successful parsed but returned no results.: ()
ERROR 2017-03-11 10:16:34,728: root: handle_failure: 1286: Successful parsed but returned no results.: ()
Traceback (most recent call last):
  File "/home/fartash/anaconda3/envs/Etl-boilerplate/lib/python2.7/site-packages/airflow/models.py", line 1245, in run
    result = task_copy.execute(context=context)
  File "/home/fartash/anaconda3/envs/Etl-boilerplate/lib/python2.7/site-packages/airflow/operators/python_operator.py", line 66, in execute
    return_value = self.python_callable(*self.op_args, **self.op_kwargs)
  File "/home/fartash/Dev/ETL-boilerplate/app/transformer/twitter.py", line 31, in process
    coordinates = self.__get_go_points(tweet['user']['location'])
  File "/home/fartash/Dev/ETL-boilerplate/app/transformer/twitter.py", line 101, in __get_go_points
    res = self.googlemaps_api.search(address.strip(string.punctuation + ' ')).first()
  File "/home/fartash/anaconda3/envs/Etl-boilerplate/lib/python2.7/site-packages/geolocation/main.py", line 18, in search
    return self.geocode.search(location, lat, lng)
  File "/home/fartash/anaconda3/envs/Etl-boilerplate/lib/python2.7/site-packages/geolocation/geocode/main.py", line 48, in search
    data = self.client.get_data(address=address, latitude=latitude, longitude=longitude)
  File "/home/fartash/anaconda3/envs/Etl-boilerplate/lib/python2.7/site-packages/geolocation/geocode/client.py", line 40, in get_data
    return self.send_data(self.API_URL, self.query_parameters)
  File "/home/fartash/anaconda3/envs/Etl-boilerplate/lib/python2.7/site-packages/geolocation/client.py", line 23, in send_data
    self.validator(response)
  File "/home/fartash/anaconda3/envs/Etl-boilerplate/lib/python2.7/site-packages/geolocation/validators.py", line 28, in __init__
    self.validation(response)
  File "/home/fartash/anaconda3/envs/Etl-boilerplate/lib/python2.7/site-packages/geolocation/validators.py", line 55, in validation
    self.validate_google_status(response)
  File "/home/fartash/anaconda3/envs/Etl-boilerplate/lib/python2.7/site-packages/geolocation/validators.py", line 46, in validate_google_status
    raise ApiClientException(message)
ApiClientException: Successful parsed but returned no results.
ERROR 2017-03-11 10:16:34,748: root: handle_failure: 1327: Successful parsed but returned no results.: ()
ERROR 2017-03-11 10:16:46,414: root: handle_failure: 1286: Successful parsed but returned no results.: ()
Traceback (most recent call last):
  File "/home/fartash/anaconda3/envs/Etl-boilerplate/lib/python2.7/site-packages/airflow/models.py", line 1245, in run
    result = task_copy.execute(context=context)
  File "/home/fartash/anaconda3/envs/Etl-boilerplate/lib/python2.7/site-packages/airflow/operators/python_operator.py", line 66, in execute
    return_value = self.python_callable(*self.op_args, **self.op_kwargs)
  File "/home/fartash/Dev/ETL-boilerplate/app/transformer/twitter.py", line 31, in process
    coordinates = self.__get_go_points(tweet['user']['location'])
  File "/home/fartash/Dev/ETL-boilerplate/app/transformer/twitter.py", line 101, in __get_go_points
    res = self.googlemaps_api.search(address.strip(string.punctuation + ' ')).first()
  File "/home/fartash/anaconda3/envs/Etl-boilerplate/lib/python2.7/site-packages/geolocation/main.py", line 18, in search
    return self.geocode.search(location, lat, lng)
  File "/home/fartash/anaconda3/envs/Etl-boilerplate/lib/python2.7/site-packages/geolocation/geocode/main.py", line 48, in search
    data = self.client.get_data(address=address, latitude=latitude, longitude=longitude)
  File "/home/fartash/anaconda3/envs/Etl-boilerplate/lib/python2.7/site-packages/geolocation/geocode/client.py", line 40, in get_data
    return self.send_data(self.API_URL, self.query_parameters)
  File "/home/fartash/anaconda3/envs/Etl-boilerplate/lib/python2.7/site-packages/geolocation/client.py", line 23, in send_data
    self.validator(response)
  File "/home/fartash/anaconda3/envs/Etl-boilerplate/lib/python2.7/site-packages/geolocation/validators.py", line 28, in __init__
    self.validation(response)
  File "/home/fartash/anaconda3/envs/Etl-boilerplate/lib/python2.7/site-packages/geolocation/validators.py", line 55, in validation
    self.validate_google_status(response)
  File "/home/fartash/anaconda3/envs/Etl-boilerplate/lib/python2.7/site-packages/geolocation/validators.py", line 46, in validate_google_status
    raise ApiClientException(message)
ApiClientException: Successful parsed but returned no results.
ERROR 2017-03-11 10:16:46,434: root: handle_failure: 1327: Successful parsed but returned no results.: ()
ERROR 2017-03-11 10:16:57,886: root: handle_failure: 1286: Successful parsed but returned no results.: ()
Traceback (most recent call last):
  File "/home/fartash/anaconda3/envs/Etl-boilerplate/lib/python2.7/site-packages/airflow/models.py", line 1245, in run
    result = task_copy.execute(context=context)
  File "/home/fartash/anaconda3/envs/Etl-boilerplate/lib/python2.7/site-packages/airflow/operators/python_operator.py", line 66, in execute
    return_value = self.python_callable(*self.op_args, **self.op_kwargs)
  File "/home/fartash/Dev/ETL-boilerplate/app/transformer/twitter.py", line 31, in process
    coordinates = self.__get_go_points(tweet['user']['location'])
  File "/home/fartash/Dev/ETL-boilerplate/app/transformer/twitter.py", line 101, in __get_go_points
    res = self.googlemaps_api.search(address.strip(string.punctuation + ' ')).first()
  File "/home/fartash/anaconda3/envs/Etl-boilerplate/lib/python2.7/site-packages/geolocation/main.py", line 18, in search
    return self.geocode.search(location, lat, lng)
  File "/home/fartash/anaconda3/envs/Etl-boilerplate/lib/python2.7/site-packages/geolocation/geocode/main.py", line 48, in search
    data = self.client.get_data(address=address, latitude=latitude, longitude=longitude)
  File "/home/fartash/anaconda3/envs/Etl-boilerplate/lib/python2.7/site-packages/geolocation/geocode/client.py", line 40, in get_data
    return self.send_data(self.API_URL, self.query_parameters)
  File "/home/fartash/anaconda3/envs/Etl-boilerplate/lib/python2.7/site-packages/geolocation/client.py", line 23, in send_data
    self.validator(response)
  File "/home/fartash/anaconda3/envs/Etl-boilerplate/lib/python2.7/site-packages/geolocation/validators.py", line 28, in __init__
    self.validation(response)
  File "/home/fartash/anaconda3/envs/Etl-boilerplate/lib/python2.7/site-packages/geolocation/validators.py", line 55, in validation
    self.validate_google_status(response)
  File "/home/fartash/anaconda3/envs/Etl-boilerplate/lib/python2.7/site-packages/geolocation/validators.py", line 46, in validate_google_status
    raise ApiClientException(message)
ApiClientException: Successful parsed but returned no results.
ERROR 2017-03-11 10:16:57,897: root: handle_failure: 1327: Successful parsed but returned no results.: ()
ERROR 2017-03-11 10:17:19,259: root: handle_failure: 1286: Successful parsed but returned no results.: ()
Traceback (most recent call last):
  File "/home/fartash/anaconda3/envs/Etl-boilerplate/lib/python2.7/site-packages/airflow/models.py", line 1245, in run
    result = task_copy.execute(context=context)
  File "/home/fartash/anaconda3/envs/Etl-boilerplate/lib/python2.7/site-packages/airflow/operators/python_operator.py", line 66, in execute
    return_value = self.python_callable(*self.op_args, **self.op_kwargs)
  File "/home/fartash/Dev/ETL-boilerplate/app/transformer/twitter.py", line 31, in process
    coordinates = self.__get_go_points(tweet['user']['location'])
  File "/home/fartash/Dev/ETL-boilerplate/app/transformer/twitter.py", line 101, in __get_go_points
    res = self.googlemaps_api.search(address.strip(string.punctuation + ' ')).first()
  File "/home/fartash/anaconda3/envs/Etl-boilerplate/lib/python2.7/site-packages/geolocation/main.py", line 18, in search
    return self.geocode.search(location, lat, lng)
  File "/home/fartash/anaconda3/envs/Etl-boilerplate/lib/python2.7/site-packages/geolocation/geocode/main.py", line 48, in search
    data = self.client.get_data(address=address, latitude=latitude, longitude=longitude)
  File "/home/fartash/anaconda3/envs/Etl-boilerplate/lib/python2.7/site-packages/geolocation/geocode/client.py", line 40, in get_data
    return self.send_data(self.API_URL, self.query_parameters)
  File "/home/fartash/anaconda3/envs/Etl-boilerplate/lib/python2.7/site-packages/geolocation/client.py", line 23, in send_data
    self.validator(response)
  File "/home/fartash/anaconda3/envs/Etl-boilerplate/lib/python2.7/site-packages/geolocation/validators.py", line 28, in __init__
    self.validation(response)
  File "/home/fartash/anaconda3/envs/Etl-boilerplate/lib/python2.7/site-packages/geolocation/validators.py", line 55, in validation
    self.validate_google_status(response)
  File "/home/fartash/anaconda3/envs/Etl-boilerplate/lib/python2.7/site-packages/geolocation/validators.py", line 46, in validate_google_status
    raise ApiClientException(message)
ApiClientException: Successful parsed but returned no results.
ERROR 2017-03-11 10:17:19,262: root: handle_failure: 1327: Successful parsed but returned no results.: ()
ERROR 2017-03-11 10:19:05,099: root: handle_failure: 1286: local variable 'res' referenced before assignment: ()
Traceback (most recent call last):
  File "/home/fartash/anaconda3/envs/Etl-boilerplate/lib/python2.7/site-packages/airflow/models.py", line 1245, in run
    result = task_copy.execute(context=context)
  File "/home/fartash/anaconda3/envs/Etl-boilerplate/lib/python2.7/site-packages/airflow/operators/python_operator.py", line 66, in execute
    return_value = self.python_callable(*self.op_args, **self.op_kwargs)
  File "/home/fartash/Dev/ETL-boilerplate/app/transformer/twitter.py", line 31, in process
    coordinates = self.__get_go_points(tweet['user']['location'])
  File "/home/fartash/Dev/ETL-boilerplate/app/transformer/twitter.py", line 105, in __get_go_points
    if res:
UnboundLocalError: local variable 'res' referenced before assignment
ERROR 2017-03-11 10:19:05,102: root: handle_failure: 1327: local variable 'res' referenced before assignment: ()
ERROR 2017-03-11 10:19:42,199: root: handle_failure: 1286: : ()
Traceback (most recent call last):
  File "/home/fartash/anaconda3/envs/Etl-boilerplate/lib/python2.7/site-packages/airflow/models.py", line 1245, in run
    result = task_copy.execute(context=context)
  File "/home/fartash/anaconda3/envs/Etl-boilerplate/lib/python2.7/site-packages/airflow/operators/python_operator.py", line 66, in execute
    return_value = self.python_callable(*self.op_args, **self.op_kwargs)
  File "/home/fartash/Dev/ETL-boilerplate/app/transformer/twitter.py", line 31, in process
    coordinates = self.__get_go_points(tweet['user']['location'])
  File "/home/fartash/Dev/ETL-boilerplate/app/transformer/twitter.py", line 102, in __get_go_points
    res = self.googlemaps_api.search(address.strip(string.punctuation + ' ')).first()
  File "/home/fartash/anaconda3/envs/Etl-boilerplate/lib/python2.7/site-packages/geolocation/main.py", line 18, in search
    return self.geocode.search(location, lat, lng)
  File "/home/fartash/anaconda3/envs/Etl-boilerplate/lib/python2.7/site-packages/geolocation/geocode/main.py", line 48, in search
    data = self.client.get_data(address=address, latitude=latitude, longitude=longitude)
  File "/home/fartash/anaconda3/envs/Etl-boilerplate/lib/python2.7/site-packages/geolocation/geocode/client.py", line 40, in get_data
    return self.send_data(self.API_URL, self.query_parameters)
  File "/home/fartash/anaconda3/envs/Etl-boilerplate/lib/python2.7/site-packages/geolocation/client.py", line 22, in send_data
    response = requests.get(url, params=params)
  File "/home/fartash/anaconda3/envs/Etl-boilerplate/lib/python2.7/site-packages/requests/api.py", line 70, in get
    return request('get', url, params=params, **kwargs)
  File "/home/fartash/anaconda3/envs/Etl-boilerplate/lib/python2.7/site-packages/requests/api.py", line 56, in request
    return session.request(method=method, url=url, **kwargs)
  File "/home/fartash/anaconda3/envs/Etl-boilerplate/lib/python2.7/site-packages/requests/sessions.py", line 488, in request
    resp = self.send(prep, **send_kwargs)
  File "/home/fartash/anaconda3/envs/Etl-boilerplate/lib/python2.7/site-packages/requests/sessions.py", line 609, in send
    r = adapter.send(request, **kwargs)
  File "/home/fartash/anaconda3/envs/Etl-boilerplate/lib/python2.7/site-packages/requests/adapters.py", line 423, in send
    timeout=timeout
  File "/home/fartash/anaconda3/envs/Etl-boilerplate/lib/python2.7/site-packages/requests/packages/urllib3/connectionpool.py", line 600, in urlopen
    chunked=chunked)
  File "/home/fartash/anaconda3/envs/Etl-boilerplate/lib/python2.7/site-packages/requests/packages/urllib3/connectionpool.py", line 345, in _make_request
    self._validate_conn(conn)
  File "/home/fartash/anaconda3/envs/Etl-boilerplate/lib/python2.7/site-packages/requests/packages/urllib3/connectionpool.py", line 844, in _validate_conn
    conn.connect()
  File "/home/fartash/anaconda3/envs/Etl-boilerplate/lib/python2.7/site-packages/requests/packages/urllib3/connection.py", line 284, in connect
    conn = self._new_conn()
  File "/home/fartash/anaconda3/envs/Etl-boilerplate/lib/python2.7/site-packages/requests/packages/urllib3/connection.py", line 141, in _new_conn
    (self.host, self.port), self.timeout, **extra_kw)
  File "/home/fartash/anaconda3/envs/Etl-boilerplate/lib/python2.7/site-packages/requests/packages/urllib3/util/connection.py", line 60, in create_connection
    for res in socket.getaddrinfo(host, port, family, socket.SOCK_STREAM):
KeyboardInterrupt
ERROR 2017-03-11 10:19:42,205: root: handle_failure: 1327: : ()
ERROR 2017-03-11 10:22:47,358: root: handle_failure: 1286: : ()
Traceback (most recent call last):
  File "/home/fartash/anaconda3/envs/Etl-boilerplate/lib/python2.7/site-packages/airflow/models.py", line 1245, in run
    result = task_copy.execute(context=context)
  File "/home/fartash/anaconda3/envs/Etl-boilerplate/lib/python2.7/site-packages/airflow/operators/python_operator.py", line 66, in execute
    return_value = self.python_callable(*self.op_args, **self.op_kwargs)
  File "/home/fartash/Dev/ETL-boilerplate/app/transformer/twitter.py", line 31, in process
    coordinates = self.__get_go_points(tweet['user']['location'])
  File "/home/fartash/Dev/ETL-boilerplate/app/transformer/twitter.py", line 102, in __get_go_points
    res = self.googlemaps_api.search(address.strip(string.punctuation + ' ')).first()
  File "/home/fartash/anaconda3/envs/Etl-boilerplate/lib/python2.7/site-packages/geolocation/main.py", line 18, in search
    return self.geocode.search(location, lat, lng)
  File "/home/fartash/anaconda3/envs/Etl-boilerplate/lib/python2.7/site-packages/geolocation/geocode/main.py", line 48, in search
    data = self.client.get_data(address=address, latitude=latitude, longitude=longitude)
  File "/home/fartash/anaconda3/envs/Etl-boilerplate/lib/python2.7/site-packages/geolocation/geocode/client.py", line 40, in get_data
    return self.send_data(self.API_URL, self.query_parameters)
  File "/home/fartash/anaconda3/envs/Etl-boilerplate/lib/python2.7/site-packages/geolocation/client.py", line 22, in send_data
    response = requests.get(url, params=params)
  File "/home/fartash/anaconda3/envs/Etl-boilerplate/lib/python2.7/site-packages/requests/api.py", line 70, in get
    return request('get', url, params=params, **kwargs)
  File "/home/fartash/anaconda3/envs/Etl-boilerplate/lib/python2.7/site-packages/requests/api.py", line 56, in request
    return session.request(method=method, url=url, **kwargs)
  File "/home/fartash/anaconda3/envs/Etl-boilerplate/lib/python2.7/site-packages/requests/sessions.py", line 488, in request
    resp = self.send(prep, **send_kwargs)
  File "/home/fartash/anaconda3/envs/Etl-boilerplate/lib/python2.7/site-packages/requests/sessions.py", line 609, in send
    r = adapter.send(request, **kwargs)
  File "/home/fartash/anaconda3/envs/Etl-boilerplate/lib/python2.7/site-packages/requests/adapters.py", line 423, in send
    timeout=timeout
  File "/home/fartash/anaconda3/envs/Etl-boilerplate/lib/python2.7/site-packages/requests/packages/urllib3/connectionpool.py", line 600, in urlopen
    chunked=chunked)
  File "/home/fartash/anaconda3/envs/Etl-boilerplate/lib/python2.7/site-packages/requests/packages/urllib3/connectionpool.py", line 345, in _make_request
    self._validate_conn(conn)
  File "/home/fartash/anaconda3/envs/Etl-boilerplate/lib/python2.7/site-packages/requests/packages/urllib3/connectionpool.py", line 844, in _validate_conn
    conn.connect()
  File "/home/fartash/anaconda3/envs/Etl-boilerplate/lib/python2.7/site-packages/requests/packages/urllib3/connection.py", line 284, in connect
    conn = self._new_conn()
  File "/home/fartash/anaconda3/envs/Etl-boilerplate/lib/python2.7/site-packages/requests/packages/urllib3/connection.py", line 141, in _new_conn
    (self.host, self.port), self.timeout, **extra_kw)
  File "/home/fartash/anaconda3/envs/Etl-boilerplate/lib/python2.7/site-packages/requests/packages/urllib3/util/connection.py", line 73, in create_connection
    sock.connect(sa)
  File "/home/fartash/anaconda3/envs/Etl-boilerplate/lib/python2.7/socket.py", line 228, in meth
    return getattr(self._sock,name)(*args)
KeyboardInterrupt
ERROR 2017-03-11 10:22:47,441: root: handle_failure: 1327: : ()
